Workbook

Sheet metadata
A1: summary
A2: scenario | B2: Evolutionary scenario (Q matrix) we used to simulate traits X and Y
A3: matrix | B3: Matrix name designation, as in the manuscript
B4: Q1 - ER.L: Independent, equal rates; low rates
B5: Q2 - ER.M: Independent, equal rates; medium rates
B6: Q3 - ER.H: Independent, equal rates; high rates
B7: Q4 - DR.LM: Independent, directional rates; low loss, medium gain
B8: Q5 - DR.LH: Independent, directional rates; low loss, high gain
B9: Q6 - DR.MH: Independent, directional rates; medium loss, high gain
B10: Q7 - DEP1.L: Low dependency, low rates
B11: Q8 - DEP1.M: Low dependency, medium rates
B12: Q9 - DEP1.H: Low dependency, high rates
B13: Q10 - DEP2.L: High dependency, low rates
B14: Q11 - DEP2.M: High dependency, medium rates
B15: Q12 - DEP2.H: High dependency, high rates
B16: random: traits X and Y were generated randomly, disregarding the tree
A17: test.00 | B17: Count of the test taxon with X = 0 and Y = 0 across the 1,000 trials
A18: test.01 | B18: Count of the test taxon with X = 0 and Y = 1 across the 1,000 trials
A19: test.10 | B19: Count of the test taxon with X = 1 and Y = 0 across the 1,000 trials
A20: test.11 | B20: Count of the test taxon with X = 1 and Y = 1 across the 1,000 trials
A21: terminal.std.med | B21: Median standardized terminal branch length of the 1,000 test taxa
A22: acc.bb | B22: Accuracy of the Bayesian Beta-Binomial prediction method
A23: acc.nb | B23: Accuracy of the Naive Bayes prediction method
A24: acc.ind.b | B24: Accuracy of the MCMC-Discrete-Independent (BayesTraits) prediction method
A25: acc.dep.b | B25: Accuracy of the MCMC-Discrete-Dependent (BayesTraits) prediction method
A26: acc.ind.rj | B26: Accuracy of the RJMCMC-Discrete-Independent (BayesTraits) prediction method
A27: acc.dep.rj | B27: Accuracy of the RJMCMC-Discrete-Dependent (BayesTraits) prediction method
B28: Color: 0
B29: Color: 0.5
B30: Color: 1
A31: mll.bb | B31: Median log loss of the Bayesian Beta-Binomial prediction method
A32: mll.nb | B32: Median log loss of the Naive Bayes prediction method
A33: mll.ind.b | B33: Median log loss of the MCMC-Discrete-Independent (BayesTraits) prediction method
A34: mll.dep.b | B34: Median log loss of the MCMC-Discrete-Dependent (BayesTraits) prediction method
A35: mll.ind.rj | B35: Median log loss of the RJMCMC-Discrete-Independent (BayesTraits) prediction method
A36: mll.dep.rj | B36: Median log loss of the RJMCMC-Discrete-Dependent (BayesTraits) prediction method
B37: Color: Log-loss = 2.302585 [equivalent to predicted P(Y=1) = 0.1, when the true state of trait Y of the test taxon is 1, or vice versa]
B38: Color: Log-loss = 0.6931472 [equivalent to predicted P(Y=1) = 0.5]
B39: Color: Log-loss = 0.1053605 [equivalent to predicted P(Y=1) = 0.1, when the true state of trait Y of the test taxon is 0, or vice versa]
A41: ER.L-random
...

Sheet summary
A1: ALL
A2: scenario | B2: matrix | C2: test.00 | D2: test.01 | E2: test.10 | F2: test.11 | G2: terminal.std.med | I2: acc.bb | J2: acc.nb | K2: acc.ind | L2: acc.dep | M2: acc.ind.rj | N2: acc.dep.rj | P2: mll.bb | Q2: mll.nb | R2: mll.ind | S2: mll.dep | T2: mll.ind.rj | U2: mll.dep.rj
A3: ER.L | B3: Q1 | C3: =COUNTIF(ER.L!E2:E1001,"00") -> 305 | D3: =COUNTIF(ER.L!E2:E1001,"01") -> 195 | E3: =COUNTIF(ER.L!E2:E1001,"10") -> 300 | F3: =COUNTIF(ER.L!E2:E1001,"11") -> 200 | G3: =MEDIAN(ER.L!H2:H1001) -> 0.082413826 | I3: =COUNTIF(ER.L!O2:O1001,100)/1000 -> 0.65 | J3: =COUNTIF(ER.L!P2:P1001,100)/1000 -> 0.668 | K3: =COUNTIF(ER.L!Q2:Q1001,100)/1000 -> 0.903 | L3: =COUNTIF(ER.L!R2:R1001,100)/1000 -> 0.886 | M3: =COUNTIF(ER.L!S2:S1001,100)/1000 -> 0.903 | N3: =COUNTIF(ER.L!T2:T1001,100)/1000 -> 0.899 | P3: =MEDIAN(ER.L!U2:U1001) -> 0.53358297 | Q3: =MEDIAN(ER.L!V2:V1001) -> 0.50259776 | R3: =MEDIAN(ER.L!W2:W1001) -> 0.091019398 | S3: =MEDIAN(ER.L!X2:X1001) -> 0.11037321 | T3: =MEDIAN(ER.L!Y2:Y1001) -> 0.075801713 | U3: =MEDIAN(ER.L!Z2:Z1001) -> 0.072570693
A4: ER.M | B4: Q2 | C4: =COUNTIF(ER.M!E2:E1001,"00") -> 236 | D4: =COUNTIF(ER.M!E2:E1001,"01") -> 264 | E4: =COUNTIF(ER.M!E2:E1001,"10") -> 272 | F4: =COUNTIF(ER.M!E2:E1001,"11") -> 228 | G4: =MEDIAN(ER.M!H2:H1001) -> 0.082904086 | I4: =COUNTIF(ER.M!O2:O1001,100)/1000 -> 0.541 | J4: =COUNTIF(ER.M!P2:P1001,100)/1000 -> 0.507 | K4: =COUNTIF(ER.M!Q2:Q1001,100)/1000 -> 0.778 | L4: =COUNTIF(ER.M!R2:R1001,100)/1000 -> 0.763 | M4: =COUNTIF(ER.M!S2:S1001,100)/1000 -> 0.786 | N4: =COUNTIF(ER.M!T2:T1001,100)/1000 -> 0.773 | P4: =MEDIAN(ER.M!U2:U1001) -> 0.67727383 | Q4: =MEDIAN(ER.M!V2:V1001) -> 0.67479186 | R4: =MEDIAN(ER.M!W2:W1001) -> 0.30788478 | S4: =MEDIAN(ER.M!X2:X1001) -> 0.37469371 | T4: =MEDIAN(ER.M!Y2:Y1001) -> 0.27246532 | U4: =MEDIAN(ER.M!Z2:Z1001) -> 0.2757535
A5: ER.H | B5: Q3 | C5: =COUNTIF(ER.H!E2:E1001,"00") -> 235 | D5: =COUNTIF(ER.H!E2:E1001,"01") -> 265 | E5: =COUNTIF(ER.H!E2:E1001,"10") -> 266 | F5: =COUNTIF(ER.H!E2:E1001,"11") -> 234 | G5: =MEDIAN(ER.H!H2:H1001) -> 0.082158161 | I5: =COUNTIF(ER.H!O2:O1001,100)/1000 -> 0.523 | J5: =COUNTIF(ER.H!P2:P1001,100)/1000 -> 0.494 | K5: =COUNTIF(ER.H!Q2:Q1001,100)/1000 -> 0.688 | L5: =COUNTIF(ER.H!R2:R1001,100)/1000 -> 0.66 | M5: =COUNTIF(ER.H!S2:S1001,100)/1000 -> 0.7 | N5: =COUNTIF(ER.H!T2:T1001,100)/1000 -> 0.668 | P5: =MEDIAN(ER.H!U2:U1001) -> 0.68716511 | Q5: =MEDIAN(ER.H!V2:V1001) -> 0.69314718 | R5: =MEDIAN(ER.H!W2:W1001) -> 0.55512588 | S5: =MEDIAN(ER.H!X2:X1001) -> 0.57536454 | T5: =MEDIAN(ER.H!Y2:Y1001) -> 0.55164762 | U5: =MEDIAN(ER.H!Z2:Z1001) -> 0.5464528
A6: DR.LM | B6: Q4 | C6: =COUNTIF(DR.LM!E2:E1001,"00") -> 190 | D6: =COUNTIF(DR.LM!E2:E1001,"01") -> 310 | E6: =COUNTIF(DR.LM!E2:E1001,"10") -> 192 | F6: =COUNTIF(DR.LM!E2:E1001,"11") -> 308 | G6: =MEDIAN(DR.LM!H2:H1001) -> 0.088567089 | I6: =COUNTIF(DR.LM!O2:O1001,100)/1000 -> 0.625 | J6: =COUNTIF(DR.LM!P2:P1001,100)/1000 -> 0.616 | K6: =COUNTIF(DR.LM!Q2:Q1001,100)/1000 -> 0.824 | L6: =COUNTIF(DR.LM!R2:R1001,100)/1000 -> 0.81 | M6: =COUNTIF(DR.LM!S2:S1001,100)/1000 -> 0.835 | N6: =COUNTIF(DR.LM!T2:T1001,100)/1000 -> 0.838 | P6: =MEDIAN(DR.LM!U2:U1001) -> 0.54472718 | Q6: =MEDIAN(DR.LM!V2:V1001) -> 0.53408249 | R6: =MEDIAN(DR.LM!W2:W1001) -> 0.15723895 | S6: =MEDIAN(DR.LM!X2:X1001) -> 0.18092272 | T6: =MEDIAN(DR.LM!Y2:Y1001) -> 0.1346749 | U6: =MEDIAN(DR.LM!Z2:Z1001) -> 0.12897038
A7: DR.LH | B7: Q5 | C7: =COUNTIF(DR.LH!E2:E1001,"00") -> 93 | D7: =COUNTIF(DR.LH!E2:E1001,"01") -> 407 | E7: =COUNTIF(DR.LH!E2:E1001,"10") -> 96 | F7: =COUNTIF(DR.LH!E2:E1001,"11") -> 404 | G7: =MEDIAN(DR.LH!H2:H1001) -> 0.08757012 | I7: =COUNTIF(DR.LH!O2:O1001,100)/1000 -> 0.811 | J7: =COUNTIF(DR.LH!P2:P1001,100)/1000 -> 0.809 | K7: =COUNTIF(DR.LH!Q2:Q1001,100)/1000 -> 0.857 | L7: =COUNTIF(DR.LH!R2:R1001,100)/1000 -> 0.852 | M7: =COUNTIF(DR.LH!S2:S1001,100)/1000 -> 0.859 | N7: =COUNTIF(DR.LH!T2:T1001,100)/1000 -> 0.857 | P7: =MEDIAN(DR.LH!U2:U1001) -> 0.22564668 | Q7: =MEDIAN(DR.LH!V2:V1001) -> 0.22184316 | R7: =MEDIAN(DR.LH!W2:W1001) -> 0.11822079 | S7: =MEDIAN(DR.LH!X2:X1001) -> 0.13296029 | T7: =MEDIAN(DR.LH!Y2:Y1001) -> 0.10869942 | U7: =MEDIAN(DR.LH!Z2:Z1001) -> 0.10925714
A8: DR.MH | B8: Q6 | C8: =COUNTIF(DR.MH!E2:E1001,"00") -> 183 | D8: =COUNTIF(DR.MH!E2:E1001,"01") -> 317 | E8: =COUNTIF(DR.MH!E2:E1001,"10") -> 158 | F8: =COUNTIF(DR.MH!E2:E1001,"11") -> 342 | G8: =MEDIAN(DR.MH!H2:H1001) -> 0.086048179 | I8: =COUNTIF(DR.MH!O2:O1001,100)/1000 -> 0.657 | J8: =COUNTIF(DR.MH!P2:P1001,100)/1000 -> 0.641 | K8: =COUNTIF(DR.MH!Q2:Q1001,100)/1000 -> 0.766 | L8: =COUNTIF(DR.MH!R2:R1001,100)/1000 -> 0.746 | M8: =COUNTIF(DR.MH!S2:S1001,100)/1000 -> 0.776 | N8: =COUNTIF(DR.MH!T2:T1001,100)/1000 -> 0.742 | P8: =MEDIAN(DR.MH!U2:U1001) -> 0.49020667 | Q8: =MEDIAN(DR.MH!V2:V1001) -> 0.51480971 | R8: =MEDIAN(DR.MH!W2:W1001) -> 0.34743233 | S8: =MEDIAN(DR.MH!X2:X1001) -> 0.37251401 | T8: =MEDIAN(DR.MH!Y2:Y1001) -> 0.31197477 | U8: =MEDIAN(DR.MH!Z2:Z1001) -> 0.34108285
A9: DEP1.L | B9: Q7 | C9: =COUNTIF('DEP1.L'!E2:E1001,"00") -> 334 | D9: =COUNTIF('DEP1.L'!E2:E1001,"01") -> 166 | E9: =COUNTIF('DEP1.L'!E2:E1001,"10") -> 214 | F9: =COUNTIF('DEP1.L'!E2:E1001,"11") -> 286 | G9: =MEDIAN('DEP1.L'!H2:H1001) -> 0.082433675 | I9: =COUNTIF('DEP1.L'!O2:O1001,100)/1000 -> 0.608 | J9: =COUNTIF('DEP1.L'!P2:P1001,100)/1000 -> 0.652 | K9: =COUNTIF('DEP1.L'!Q2:Q1001,100)/1000 -> 0.888 | L9: =COUNTIF('DEP1.L'!R2:R1001,100)/1000 -> 0.858 | M9: =COUNTIF('DEP1.L'!S2:S1001,100)/1000 -> 0.886 | N9: =COUNTIF('DEP1.L'!T2:T1001,100)/1000 -> 0.873 | P9: =MEDIAN('DEP1.L'!U2:U1001) -> 0.59239728 | Q9: =MEDIAN('DEP1.L'!V2:V1001) -> 0.51331939 | R9: =MEDIAN('DEP1.L'!W2:W1001) -> 0.10425002 | S9: =MEDIAN('DEP1.L'!X2:X1001) -> 0.12613044 | T9: =MEDIAN('DEP1.L'!Y2:Y1001) -> 0.082295243 | U9: =MEDIAN('DEP1.L'!Z2:Z1001) -> 0.086647807
A10: DEP1.M | B10: Q8 | C10: =COUNTIF('DEP1.M'!E2:E1001,"00") -> 268 | D10: =COUNTIF('DEP1.M'!E2:E1001,"01") -> 232 | E10: =COUNTIF('DEP1.M'!E2:E1001,"10") -> 159 | F10: =COUNTIF('DEP1.M'!E2:E1001,"11") -> 341 | G10: =MEDIAN('DEP1.M'!H2:H1001) -> 0.08696674 | I10: =COUNTIF('DEP1.M'!O2:O1001,100)/1000 -> 0.587 | J10: =COUNTIF('DEP1.M'!P2:P1001,100)/1000 -> 0.612 | K10: =COUNTIF('DEP1.M'!Q2:Q1001,100)/1000 -> 0.798 | L10: =COUNTIF('DEP1.M'!R2:R1001,100)/1000 -> 0.772 | M10: =COUNTIF('DEP1.M'!S2:S1001,100)/1000 -> 0.796 | N10: =COUNTIF('DEP1.M'!T2:T1001,100)/1000 -> 0.795 | P10: =MEDIAN('DEP1.M'!U2:U1001) -> 0.65200524 | Q10: =MEDIAN('DEP1.M'!V2:V1001) -> 0.60299608 | R10: =MEDIAN('DEP1.M'!W2:W1001) -> 0.2890163 | S10: =MEDIAN('DEP1.M'!X2:X1001) -> 0.29504265 | T10: =MEDIAN('DEP1.M'!Y2:Y1001) -> 0.25102875 | U10: =MEDIAN('DEP1.M'!Z2:Z1001) -> 0.23762307
A11: DEP1.H | B11: Q9 | C11: =COUNTIF('DEP1.H'!E2:E1001,"00") -> 253 | D11: =COUNTIF('DEP1.H'!E2:E1001,"01") -> 247 | E11: =COUNTIF('DEP1.H'!E2:E1001,"10") -> 152 | F11: =COUNTIF('DEP1.H'!E2:E1001,"11") -> 348 | G11: =MEDIAN('DEP1.H'!H2:H1001) -> 0.081043346 | I11: =COUNTIF('DEP1.H'!O2:O1001,100)/1000 -> 0.576 | J11: =COUNTIF('DEP1.H'!P2:P1001,100)/1000 -> 0.601 | K11: =COUNTIF('DEP1.H'!Q2:Q1001,100)/1000 -> 0.693 | L11: =COUNTIF('DEP1.H'!R2:R1001,100)/1000 -> 0.702 | M11: =COUNTIF('DEP1.H'!S2:S1001,100)/1000 -> 0.691 | N11: =COUNTIF('DEP1.H'!T2:T1001,100)/1000 -> 0.707 | P11: =MEDIAN('DEP1.H'!U2:U1001) -> 0.65488893 | Q11: =MEDIAN('DEP1.H'!V2:V1001) -> 0.61373539 | R11: =MEDIAN('DEP1.H'!W2:W1001) -> 0.48939034 | S11: =MEDIAN('DEP1.H'!X2:X1001) -> 0.4533435 | T11: =MEDIAN('DEP1.H'!Y2:Y1001) -> 0.50087529 | U11: =MEDIAN('DEP1.H'!Z2:Z1001) -> 0.42312004
A12: DEP2.L | B12: Q10 | C12: =COUNTIF('DEP2.L'!E2:E1001,"00") -> 305 | D12: =COUNTIF('DEP2.L'!E2:E1001,"01") -> 199 | E12: =COUNTIF('DEP2.L'!E2:E1001,"10") -> 72 | F12: =COUNTIF('DEP2.L'!E2:E1001,"11") -> 424 | G12: =MEDIAN('DEP2.L'!H2:H1001) -> 0.092310217 | I12: =COUNTIF('DEP2.L'!O2:O1001,100)/1000 -> 0.567 | J12: =COUNTIF('DEP2.L'!P2:P1001,100)/1000 -> 0.746 | K12: =COUNTIF('DEP2.L'!Q2:Q1001,100)/1000 -> 0.887 | L12: =COUNTIF('DEP2.L'!R2:R1001,100)/1000 -> 0.887 | M12: =COUNTIF('DEP2.L'!S2:S1001,100)/1000 -> 0.89 | N12: =COUNTIF('DEP2.L'!T2:T1001,100)/1000 -> 0.905 | P12: =MEDIAN('DEP2.L'!U2:U1001) -> 0.63487827 | Q12: =MEDIAN('DEP2.L'!V2:V1001) -> 0.35262789 | R12: =MEDIAN('DEP2.L'!W2:W1001) -> 0.10981487 | S12: =MEDIAN('DEP2.L'!X2:X1001) -> 0.075801713 | T12: =MEDIAN('DEP2.L'!Y2:Y1001) -> 0.090472053 | U12: =MEDIAN('DEP2.L'!Z2:Z1001) -> 0.05551271
A13: DEP2.M | B13: Q11 | C13: =COUNTIF('DEP2.M'!E2:E1001,"00") -> 246 | D13: =COUNTIF('DEP2.M'!E2:E1001,"01") -> 254 | E13: =COUNTIF('DEP2.M'!E2:E1001,"10") -> 39 | F13: =COUNTIF('DEP2.M'!E2:E1001,"11") -> 461 | G13: =MEDIAN('DEP2.M'!H2:H1001) -> 0.079486345 | I13: =COUNTIF('DEP2.M'!O2:O1001,100)/1000 -> 0.656 | J13: =COUNTIF('DEP2.M'!P2:P1001,100)/1000 -> 0.731 | K13: =COUNTIF('DEP2.M'!Q2:Q1001,100)/1000 -> 0.828 | L13: =COUNTIF('DEP2.M'!R2:R1001,100)/1000 -> 0.854 | M13: =COUNTIF('DEP2.M'!S2:S1001,100)/1000 -> 0.827 | N13: =COUNTIF('DEP2.M'!T2:T1001,100)/1000 -> 0.856 | P13: =MEDIAN('DEP2.M'!U2:U1001) -> 0.58071215 | Q13: =MEDIAN('DEP2.M'!V2:V1001) -> 0.42744401 | R13: =MEDIAN('DEP2.M'!W2:W1001) -> 0.22690139 | S13: =MEDIAN('DEP2.M'!X2:X1001) -> 0.11991093 | T13: =MEDIAN('DEP2.M'!Y2:Y1001) -> 0.20702417 | U13: =MEDIAN('DEP2.M'!Z2:Z1001) -> 0.12613044
A14: DEP2.H | B14: Q12 | C14: =COUNTIF('DEP2.H'!E2:E1001,"00") -> 262 | D14: =COUNTIF('DEP2.H'!E2:E1001,"01") -> 238 | E14: =COUNTIF('DEP2.H'!E2:E1001,"10") -> 40 | F14: =COUNTIF('DEP2.H'!E2:E1001,"11") -> 460 | G14: =MEDIAN('DEP2.H'!H2:H1001) -> 0.080324121 | I14: =COUNTIF('DEP2.H'!O2:O1001,100)/1000 -> 0.689 | J14: =COUNTIF('DEP2.H'!P2:P1001,100)/1000 -> 0.7 | K14: =COUNTIF('DEP2.H'!Q2:Q1001,100)/1000 -> 0.765 | L14: =COUNTIF('DEP2.H'!R2:R1001,100)/1000 -> 0.79 | M14: =COUNTIF('DEP2.H'!S2:S1001,100)/1000 -> 0.766 | N14: =COUNTIF('DEP2.H'!T2:T1001,100)/1000 -> 0.802 | P14: =MEDIAN('DEP2.H'!U2:U1001) -> 0.51082562 | Q14: =MEDIAN('DEP2.H'!V2:V1001) -> 0.48465238 | R14: =MEDIAN('DEP2.H'!W2:W1001) -> 0.37614932 | S14: =MEDIAN('DEP2.H'!X2:X1001) -> 0.20211693 | T14: =MEDIAN('DEP2.H'!Y2:Y1001) -> 0.35382187 | U14: =MEDIAN('DEP2.H'!Z2:Z1001) -> 0.20456792
A15: random | B15: random | C15: =COUNTIF(random!E2:E1001,"00") -> 244 | D15: =COUNTIF(random!E2:E1001,"01") -> 256 | E15: =COUNTIF(random!E2:E1001,"10") -> 261 | F15: =COUNTIF(random!E2:E1001,"11") -> 239 | G15: =MEDIAN(random!H2:H1001) -> 0.085709442 | I15: =COUNTIF(random!O2:O1001,100)/1000 -> 0.48 | J15: =COUNTIF(random!P2:P1001,100)/1000 -> 0.47 | K15: =COUNTIF(random!Q2:Q1001,100)/1000 -> 0.514 | L15: =COUNTIF(random!R2:R1001,100)/1000 -> 0.516 | M15: =COUNTIF(random!S2:S1001,100)/1000 -> 0.524 | N15: =COUNTIF(random!T2:T1001,100)/1000 -> 0.517 | P15: =MEDIAN(random!U2:U1001) -> 0.6971552 | Q15: =MEDIAN(random!V2:V1001) -> 0.69314718 | R15: =MEDIAN(random!W2:W1001) -> 0.68915516 | S15: =MEDIAN(random!X2:X1001) -> 0.68517901 | T15: =MEDIAN(random!Y2:Y1001) -> 0.69114918 | U15: =MEDIAN(random!Z2:Z1001) -> 0.68915516
A17: TRUE STATE OF TEST TAXON: 00
A18: scenario | B18: matrix | C18: test.00 | D18: test.01 | E18: test.10 | F18: test.11 | G18: terminal.std.med | I18: acc.bb | J18: acc.nb | K18: acc.ind | L18: acc.dep | M18: acc.ind.rj | N18: acc.dep.rj | P18: mll.bb | Q18: mll.nb | R18: mll.ind | S18: mll.dep | T18: mll.ind.rj | U18: mll.dep.rj
A19: ER.L | B19: Q1 | C19: =C3 -> 305 | D19: 0 | E19: 0 | F19: 0 | G19: {=MEDIAN(IF(ER.L!$E$2:$E$1001="00",ER.L!H2:H1001))} -> 0.078539747 | I19: =COUNTIFS(ER.L!O2:O1001,100,ER.L!$E$2:$E$1001,"00")/$C$19 -> 0.8557377 | J19: =COUNTIFS(ER.L!P2:P1001,100,ER.L!$E$2:$E$1001,"00")/$C$19 -> 0.86229508 | K19: =COUNTIFS(ER.L!Q2:Q1001,100,ER.L!$E$2:$E$1001,"00")/$C$19 -> 0.94754098 | L19: =COUNTIFS(ER.L!R2:R1001,100,ER.L!$E$2:$E$1001,"00")/$C$19 -> 0.94754098 | M19: =COUNTIFS(ER.L!S2:S1001,100,ER.L!$E$2:$E$1001,"00")/$C$19 -> 0.94754098 | N19: =COUNTIFS(ER.L!T2:T1001,100,ER.L!$E$2:$E$1001,"00")/$C$19 -> 0.95081967 | P19: {=MEDIAN(IF(ER.L!$E$2:$E$1001="00",ER.L!U2:U1001))} -> 0.40947313 | Q19: {=MEDIAN(IF(ER.L!$E$2:$E$1001="00",ER.L!V2:V1001))} -> 0.35894509 | R19: {=MEDIAN(IF(ER.L!$E$2:$E$1001="00",ER.L!W2:W1001))} -> 0.071496002 | S19: {=MEDIAN(IF(ER.L!$E$2:$E$1001="00",ER.L!X2:X1001))} -> 0.076881044 | T19: {=MEDIAN(IF(ER.L!$E$2:$E$1001="00",ER.L!Y2:Y1001))} -> 0.066139803 | U19: {=MEDIAN(IF(ER.L!$E$2:$E$1001="00",ER.L!Z2:Z1001))} -> 0.06400533
A20: ER.M | B20: Q2 | C20: =C4 -> 236 | D20: 0 | E20: 0 | F20: 0 | G20: {=MEDIAN(IF(ER.M!$E$2:$E$1001="00",ER.M!H2:H1001))} -> 0.086671999 | I20: =COUNTIFS(ER.M!O2:O1001,100,ER.M!$E$2:$E$1001,"00")/$C$20 -> 0.63135593 | J20: =COUNTIFS(ER.M!P2:P1001,100,ER.M!$E$2:$E$1001,"00")/$C$20 -> 0.54237288 | K20: =COUNTIFS(ER.M!Q2:Q1001,100,ER.M!$E$2:$E$1001,"00")/$C$20 -> 0.76694915 | L20: =COUNTIFS(ER.M!R2:R1001,100,ER.M!$E$2:$E$1001,"00")/$C$20 -> 0.75847458 | M20: =COUNTIFS(ER.M!S2:S1001,100,ER.M!$E$2:$E$1001,"00")/$C$20 -> 0.77966102 | N20: =COUNTIFS(ER.M!T2:T1001,100,ER.M!$E$2:$E$1001,"00")/$C$20 -> 0.77966102 | P20: {=MEDIAN(IF(ER.M!$E$2:$E$1001="00",ER.M!U2:U1001))} -> 0.63771292 | Q20: {=MEDIAN(IF(ER.M!$E$2:$E$1001="00",ER.M!V2:V1001))} -> 0.65980149 | R20: {=MEDIAN(IF(ER.M!$E$2:$E$1001="00",ER.M!W2:W1001))} -> 0.32434701 | S20: {=MEDIAN(IF(ER.M!$E$2:$E$1001="00",ER.M!X2:X1001))} -> 0.3739675 | T20: {=MEDIAN(IF(ER.M!$E$2:$E$1001="00",ER.M!Y2:Y1001))} -> 0.30313441 | U20: {=MEDIAN(IF(ER.M!$E$2:$E$1001="00",ER.M!Z2:Z1001))} -> 0.30856737
A21: ER.H | B21: Q3 | C21: =C5 -> 235 | D21: 0 | E21: 0 | F21: 0 | G21: {=MEDIAN(IF(ER.H!$E$2:$E$1001="00",ER.H!H2:H1001))} -> 0.080704297 | I21: =COUNTIFS(ER.H!O2:O1001,100,ER.H!$E$2:$E$1001,"00")/$C$21 -> 0.47659574 | J21: =COUNTIFS(ER.H!P2:P1001,100,ER.H!$E$2:$E$1001,"00")/$C$21 -> 0.49787234 | K21: =COUNTIFS(ER.H!Q2:Q1001,100,ER.H!$E$2:$E$1001,"00")/$C$21 -> 0.68510638 | L21: =COUNTIFS(ER.H!R2:R1001,100,ER.H!$E$2:$E$1001,"00")/$C$21 -> 0.66808511 | M21: =COUNTIFS(ER.H!S2:S1001,100,ER.H!$E$2:$E$1001,"00")/$C$21 -> 0.70212766 | N21: =COUNTIFS(ER.H!T2:T1001,100,ER.H!$E$2:$E$1001,"00")/$C$21 -> 0.66808511 | P21: {=MEDIAN(IF(ER.H!$E$2:$E$1001="00",ER.H!U2:U1001))} -> 0.70521976 | Q21: {=MEDIAN(IF(ER.H!$E$2:$E$1001="00",ER.H!V2:V1001))} -> 0.69314718 | R21: {=MEDIAN(IF(ER.H!$E$2:$E$1001="00",ER.H!W2:W1001))} -> 0.57447565 | S21: {=MEDIAN(IF(ER.H!$E$2:$E$1001="00",ER.H!X2:X1001))} -> 0.58339632 | T21: {=MEDIAN(IF(ER.H!$E$2:$E$1001="00",ER.H!Y2:Y1001))} -> 0.56036607 | U21: {=MEDIAN(IF(ER.H!$E$2:$E$1001="00",ER.H!Z2:Z1001))} -> 0.58519004
A22: DR.LM | B22: Q4 | C22: =C6 -> 190 | D22: 0 | E22: 0 | F22: 0 | G22: {=MEDIAN(IF(DR.LM!$E$2:$E$1001="00",DR.LM!H2:H1001))} -> 0.093810904 | I22: =COUNTIFS(DR.LM!O2:O1001,100,DR.LM!$E$2:$E$1001,"00")/$C$22 -> 0.14210526 | J22: =COUNTIFS(DR.LM!P2:P1001,100,DR.LM!$E$2:$E$1001,"00")/$C$22 -> 0.21052632 | K22: =COUNTIFS(DR.LM!Q2:Q1001,100,DR.LM!$E$2:$E$1001,"00")/$C$22 -> 0.7 | L22: =COUNTIFS(DR.LM!R2:R1001,100,DR.LM!$E$2:$E$1001,"00")/$C$22 -> 0.64736842 | M22: =COUNTIFS(DR.LM!S2:S1001,100,DR.LM!$E$2:$E$1001,"00")/$C$22 -> 0.72105263 | N22: =COUNTIFS(DR.LM!T2:T1001,100,DR.LM!$E$2:$E$1001,"00")/$C$22 -> 0.73684211 | P22: {=MEDIAN(IF(DR.LM!$E$2:$E$1001="00",DR.LM!U2:U1001))} -> 0.97688044 | Q22: {=MEDIAN(IF(DR.LM!$E$2:$E$1001="00",DR.LM!V2:V1001))} -> 0.99182524 | R22: {=MEDIAN(IF(DR.LM!$E$2:$E$1001="00",DR.LM!W2:W1001))} -> 0.30381237 | S22: {=MEDIAN(IF(DR.LM!$E$2:$E$1001="00",DR.LM!X2:X1001))} -> 0.46203672 | T22: {=MEDIAN(IF(DR.LM!$E$2:$E$1001="00",DR.LM!Y2:Y1001))} -> 0.23067261 | U22: {=MEDIAN(IF(DR.LM!$E$2:$E$1001="00",DR.LM!Z2:Z1001))} -> 0.22127206
A23: DR.LH | B23: Q5 | C23: =C7 -> 93 | D23: 0 | E23: 0 | F23: 0 | G23: {=MEDIAN(IF(DR.LH!$E$2:$E$1001="00",DR.LH!H2:H1001))} -> 0.095319769 | I23: =COUNTIFS(DR.LH!O2:O1001,100,DR.LH!$E$2:$E$1001,"00")/$C$23 -> 0 | J23: =COUNTIFS(DR.LH!P2:P1001,100,DR.LH!$E$2:$E$1001,"00")/$C$23 -> 0.043010753 | K23: =COUNTIFS(DR.LH!Q2:Q1001,100,DR.LH!$E$2:$E$1001,"00")/$C$23 -> 0.30107527 | L23: =COUNTIFS(DR.LH!R2:R1001,100,DR.LH!$E$2:$E$1001,"00")/$C$23 -> 0.23655914 | M23: =COUNTIFS(DR.LH!S2:S1001,100,DR.LH!$E$2:$E$1001,"00")/$C$23 -> 0.33333333 | N23: =COUNTIFS(DR.LH!T2:T1001,100,DR.LH!$E$2:$E$1001,"00")/$C$23 -> 0.35483871 | P23: {=MEDIAN(IF(DR.LH!$E$2:$E$1001="00",DR.LH!U2:U1001))} -> 1.7203695 | Q23: {=MEDIAN(IF(DR.LH!$E$2:$E$1001="00",DR.LH!V2:V1001))} -> 1.8325815 | R23: {=MEDIAN(IF(DR.LH!$E$2:$E$1001="00",DR.LH!W2:W1001))} -> 1.551169 | S23: {=MEDIAN(IF(DR.LH!$E$2:$E$1001="00",DR.LH!X2:X1001))} -> 1.4828053 | T23: {=MEDIAN(IF(DR.LH!$E$2:$E$1001="00",DR.LH!Y2:Y1001))} -> 1.5945493 | U23: {=MEDIAN(IF(DR.LH!$E$2:$E$1001="00",DR.LH!Z2:Z1001))} -> 1.3167683
A24: DR.MH | B24: Q6 | C24: =C8 -> 183 | D24: 0 | E24: 0 | F24: 0 | G24: {=MEDIAN(IF(DR.MH!$E$2:$E$1001="00",DR.MH!H2:H1001))} -> 0.081674767 | I24: =COUNTIFS(DR.MH!O2:O1001,100,DR.MH!$E$2:$E$1001,"00")/$C$24 -> 0.016393443 | J24: =COUNTIFS(DR.MH!P2:P1001,100,DR.MH!$E$2:$E$1001,"00")/$C$24 -> 0.054644809 | K24: =COUNTIFS(DR.MH!Q2:Q1001,100,DR.MH!$E$2:$E$1001,"00")/$C$24 -> 0.47540984 | L24: =COUNTIFS(DR.MH!R2:R1001,100,DR.MH!$E$2:$E$1001,"00")/$C$24 -> 0.36065574 | M24: =COUNTIFS(DR.MH!S2:S1001,100,DR.MH!$E$2:$E$1001,"00")/$C$24 -> 0.56830601 | N24: =COUNTIFS(DR.MH!T2:T1001,100,DR.MH!$E$2:$E$1001,"00")/$C$24 -> 0.53005464 | P24: {=MEDIAN(IF(DR.MH!$E$2:$E$1001="00",DR.MH!U2:U1001))} -> 1.0613165 | Q24: {=MEDIAN(IF(DR.MH!$E$2:$E$1001="00",DR.MH!V2:V1001))} -> 1.0745147 | R24: {=MEDIAN(IF(DR.MH!$E$2:$E$1001="00",DR.MH!W2:W1001))} -> 0.73396918 | S24: {=MEDIAN(IF(DR.MH!$E$2:$E$1001="00",DR.MH!X2:X1001))} -> 0.93394567 | T24: {=MEDIAN(IF(DR.MH!$E$2:$E$1001="00",DR.MH!Y2:Y1001))} -> 0.63299326 | U24: {=MEDIAN(IF(DR.MH!$E$2:$E$1001="00",DR.MH!Z2:Z1001))} -> 0.597837
A25: DEP1.L | B25: Q7 | C25: =C9 -> 334 | D25: 0 | E25: 0 | F25: 0 | G25: {=MEDIAN(IF('DEP1.L'!$E$2:$E$1001="00",'DEP1.L'!H2:H1001))} -> 0.077566887 | I25: =COUNTIFS('DEP1.L'!O2:O1001,100,'DEP1.L'!$E$2:$E$1001,"00")/$C$25 -> 0.76347305 | J25: =COUNTIFS('DEP1.L'!P2:P1001,100,'DEP1.L'!$E$2:$E$1001,"00")/$C$25 -> 0.83532934 | K25: =COUNTIFS('DEP1.L'!Q2:Q1001,100,'DEP1.L'!$E$2:$E$1001,"00")/$C$25 -> 0.90718563 | L25: =COUNTIFS('DEP1.L'!R2:R1001,100,'DEP1.L'!$E$2:$E$1001,"00")/$C$25 -> 0.91916168 | M25: =COUNTIFS('DEP1.L'!S2:S1001,100,'DEP1.L'!$E$2:$E$1001,"00")/$C$25 -> 0.90419162 | N25: =COUNTIFS('DEP1.L'!T2:T1001,100,'DEP1.L'!$E$2:$E$1001,"00")/$C$25 -> 0.89820359 | P25: {=MEDIAN(IF('DEP1.L'!$E$2:$E$1001="00",'DEP1.L'!U2:U1001))} -> 0.50749921 | Q25: {=MEDIAN(IF('DEP1.L'!$E$2:$E$1001="00",'DEP1.L'!V2:V1001))} -> 0.40253255 | R25: {=MEDIAN(IF('DEP1.L'!$E$2:$E$1001="00",'DEP1.L'!W2:W1001))} -> 0.095960543 | S25: {=MEDIAN(IF('DEP1.L'!$E$2:$E$1001="00",'DEP1.L'!X2:X1001))} -> 0.098168052 | T25: {=MEDIAN(IF('DEP1.L'!$E$2:$E$1001="00",'DEP1.L'!Y2:Y1001))} -> 0.071496002 | U25: {=MEDIAN(IF('DEP1.L'!$E$2:$E$1001="00",'DEP1.L'!Z2:Z1001))} -> 0.079584626
A26: DEP1.M | B26: Q8 | C26: =C10 -> 268 | D26: 0 | E26: 0 | F26: 0 | G26: {=MEDIAN(IF('DEP1.M'!$E$2:$E$1001="00",'DEP1.M'!H2:H1001))} -> 0.086412454 | I26: =COUNTIFS('DEP1.M'!O2:O1001,100,'DEP1.M'!$E$2:$E$1001,"00")/$C$26 -> 0.30223881 | J26: =COUNTIFS('DEP1.M'!P2:P1001,100,'DEP1.M'!$E$2:$E$1001,"00")/$C$26 -> 0.59328358 | K26: =COUNTIFS('DEP1.M'!Q2:Q1001,100,'DEP1.M'!$E$2:$E$1001,"00")/$C$26 -> 0.72014925 | L26: =COUNTIFS('DEP1.M'!R2:R1001,100,'DEP1.M'!$E$2:$E$1001,"00")/$C$26 -> 0.81343284 | M26: =COUNTIFS('DEP1.M'!S2:S1001,100,'DEP1.M'!$E$2:$E$1001,"00")/$C$26 -> 0.74253731 | N26: =COUNTIFS('DEP1.M'!T2:T1001,100,'DEP1.M'!$E$2:$E$1001,"00")/$C$26 -> 0.78358209 | P26: {=MEDIAN(IF('DEP1.M'!$E$2:$E$1001="00",'DEP1.M'!U2:U1001))} -> 0.78088609 | Q26: {=MEDIAN(IF('DEP1.M'!$E$2:$E$1001="00",'DEP1.M'!V2:V1001))} -> 0.64588256 | R26: {=MEDIAN(IF('DEP1.M'!$E$2:$E$1001="00",'DEP1.M'!W2:W1001))} -> 0.32850407 | S26: {=MEDIAN(IF('DEP1.M'!$E$2:$E$1001="00",'DEP1.M'!X2:X1001))} -> 0.32919899 | T26: {=MEDIAN(IF('DEP1.M'!$E$2:$E$1001="00",'DEP1.M'!Y2:Y1001))} -> 0.24080577 | U26: {=MEDIAN(IF('DEP1.M'!$E$2:$E$1001="00",'DEP1.M'!Z2:Z1001))} -> 0.28369005
A27: DEP1.H | B27: Q9 | C27: =C11 -> 253 | D27: 0 | E27: 0 | F27: 0 | G27: {=MEDIAN(IF('DEP1.H'!$E$2:$E$1001="00",'DEP1.H'!H2:H1001))} -> 0.07349074 | I27: =COUNTIFS('DEP1.H'!O2:O1001,100,'DEP1.H'!$E$2:$E$1001,"00")/$C$27 -> 0.13438735 | J27: =COUNTIFS('DEP1.H'!P2:P1001,100,'DEP1.H'!$E$2:$E$1001,"00")/$C$27 -> 0.52964427 | K27: =COUNTIFS('DEP1.H'!Q2:Q1001,100,'DEP1.H'!$E$2:$E$1001,"00")/$C$27 -> 0.46640316 | L27: =COUNTIFS('DEP1.H'!R2:R1001,100,'DEP1.H'!$E$2:$E$1001,"00")/$C$27 -> 0.64822134 | M27: =COUNTIFS('DEP1.H'!S2:S1001,100,'DEP1.H'!$E$2:$E$1001,"00")/$C$27 -> 0.58102767 | N27: =COUNTIFS('DEP1.H'!T2:T1001,100,'DEP1.H'!$E$2:$E$1001,"00")/$C$27 -> 0.66007905 | P27: {=MEDIAN(IF('DEP1.H'!$E$2:$E$1001="00",'DEP1.H'!U2:U1001))} -> 0.85802182 | Q27: {=MEDIAN(IF('DEP1.H'!$E$2:$E$1001="00",'DEP1.H'!V2:V1001))} -> 0.67512868 | R27: {=MEDIAN(IF('DEP1.H'!$E$2:$E$1001="00",'DEP1.H'!W2:W1001))} -> 0.72360639 | S27: {=MEDIAN(IF('DEP1.H'!$E$2:$E$1001="00",'DEP1.H'!X2:X1001))} -> 0.59420723 | T27: {=MEDIAN(IF('DEP1.H'!$E$2:$E$1001="00",'DEP1.H'!Y2:Y1001))} -> 0.64245407 | U27: {=MEDIAN(IF('DEP1.H'!$E$2:$E$1001="00",'DEP1.H'!Z2:Z1001))} -> 0.55164762
A28: DEP2.L | B28: Q10 | C28: =C12 -> 305 | D28: 0 | E28: 0 | F28: 0 | G28: {=MEDIAN(IF('DEP2.L'!$E$2:$E$1001="00",'DEP2.L'!H2:H1001))} -> 0.097008128 | I28: =COUNTIFS('DEP2.L'!O2:O1001,100,'DEP2.L'!$E$2:$E$1001,"00")/$C$28 -> 0.72459016 | J28: =COUNTIFS('DEP2.L'!P2:P1001,100,'DEP2.L'!$E$2:$E$1001,"00")/$C$28 -> 0.86885246 | K28: =COUNTIFS('DEP2.L'!Q2:Q1001,100,'DEP2.L'!$E$2:$E$1001,"00")/$C$28 -> 0.91147541 | L28: =COUNTIFS('DEP2.L'!R2:R1001,100,'DEP2.L'!$E$2:$E$1001,"00")/$C$28 -> 0.92131148 | M28: =COUNTIFS('DEP2.L'!S2:S1001,100,'DEP2.L'!$E$2:$E$1001,"00")/$C$28 -> 0.91803279 | N28: =COUNTIFS('DEP2.L'!T2:T1001,100,'DEP2.L'!$E$2:$E$1001,"00")/$C$28 -> 0.93114754 | P28: {=MEDIAN(IF('DEP2.L'!$E$2:$E$1001="00",'DEP2.L'!U2:U1001))} -> 0.51583817 | Q28: {=MEDIAN(IF('DEP2.L'!$E$2:$E$1001="00",'DEP2.L'!V2:V1001))} -> 0.40546511 | R28: {=MEDIAN(IF('DEP2.L'!$E$2:$E$1001="00",'DEP2.L'!W2:W1001))} -> 0.12669765 | S28: {=MEDIAN(IF('DEP2.L'!$E$2:$E$1001="00",'DEP2.L'!X2:X1001))} -> 0.1131687 | T28: {=MEDIAN(IF('DEP2.L'!$E$2:$E$1001="00",'DEP2.L'!Y2:Y1001))} -> 0.094310679 | U28: {=MEDIAN(IF('DEP2.L'!$E$2:$E$1001="00",'DEP2.L'!Z2:Z1001))} -> 0.10758521
A29: DEP2.M | B29: Q11 | C29: =C13 -> 246 | D29: 0 | E29: 0 | F29: 0 | G29: {=MEDIAN(IF('DEP2.M'!$E$2:$E$1001="00",'DEP2.M'!H2:H1001))} -> 0.077026378 | I29: =COUNTIFS('DEP2.M'!O2:O1001,100,'DEP2.M'!$E$2:$E$1001,"00")/$C$29 -> 0.18292683 | J29: =COUNTIFS('DEP2.M'!P2:P1001,100,'DEP2.M'!$E$2:$E$1001,"00")/$C$29 -> 0.67073171 | K29: =COUNTIFS('DEP2.M'!Q2:Q1001,100,'DEP2.M'!$E$2:$E$1001,"00")/$C$29 -> 0.67886179 | L29: =COUNTIFS('DEP2.M'!R2:R1001,100,'DEP2.M'!$E$2:$E$1001,"00")/$C$29 -> 0.80487805 | M29: =COUNTIFS('DEP2.M'!S2:S1001,100,'DEP2.M'!$E$2:$E$1001,"00")/$C$29 -> 0.7195122 | N29: =COUNTIFS('DEP2.M'!T2:T1001,100,'DEP2.M'!$E$2:$E$1001,"00")/$C$29 -> 0.81300813 | P29: {=MEDIAN(IF('DEP2.M'!$E$2:$E$1001="00",'DEP2.M'!U2:U1001))} -> 0.89281912 | Q29: {=MEDIAN(IF('DEP2.M'!$E$2:$E$1001="00",'DEP2.M'!V2:V1001))} -> 0.60819766 | R29: {=MEDIAN(IF('DEP2.M'!$E$2:$E$1001="00",'DEP2.M'!W2:W1001))} -> 0.38492773 | S29: {=MEDIAN(IF('DEP2.M'!$E$2:$E$1001="00",'DEP2.M'!X2:X1001))} -> 0.31402628 | T29: {=MEDIAN(IF('DEP2.M'!$E$2:$E$1001="00",'DEP2.M'!Y2:Y1001))} -> 0.32573398 | U29: {=MEDIAN(IF('DEP2.M'!$E$2:$E$1001="00",'DEP2.M'!Z2:Z1001))} -> 0.29035319
A30: DEP2.H | B30: Q12 | C30: =C14 -> 262 | D30: 0 | E30: 0 | F30: 0 | G30: {=MEDIAN(IF('DEP2.H'!$E$2:$E$1001="00",'DEP2.H'!H2:H1001))} -> 0.10345051 | I30: =COUNTIFS('DEP2.H'!O2:O1001,100,'DEP2.H'!$E$2:$E$1001,"00")/$C$30 -> 0.022900763 | J30: =COUNTIFS('DEP2.H'!P2:P1001,100,'DEP2.H'!$E$2:$E$1001,"00")/$C$30 -> 0.50763359 | K30: =COUNTIFS('DEP2.H'!Q2:Q1001,100,'DEP2.H'!$E$2:$E$1001,"00")/$C$30 -> 0.38549618 | L30: =COUNTIFS('DEP2.H'!R2:R1001,100,'DEP2.H'!$E$2:$E$1001,"00")/$C$30 -> 0.63740458 | M30: =COUNTIFS('DEP2.H'!S2:S1001,100,'DEP2.H'!$E$2:$E$1001,"00")/$C$30 -> 0.46183206 | N30: =COUNTIFS('DEP2.H'!T2:T1001,100,'DEP2.H'!$E$2:$E$1001,"00")/$C$30 -> 0.66030534 | P30: {=MEDIAN(IF('DEP2.H'!$E$2:$E$1001="00",'DEP2.H'!U2:U1001))} -> 1.0300195 | Q30: {=MEDIAN(IF('DEP2.H'!$E$2:$E$1001="00",'DEP2.H'!V2:V1001))} -> 0.67935123 | R30: {=MEDIAN(IF('DEP2.H'!$E$2:$E$1001="00",'DEP2.H'!W2:W1001))} -> 0.86631151 | S30: {=MEDIAN(IF('DEP2.H'!$E$2:$E$1001="00",'DEP2.H'!X2:X1001))} -> 0.57181529 | T30: {=MEDIAN(IF('DEP2.H'!$E$2:$E$1001="00",'DEP2.H'!Y2:Y1001))} -> 0.73501628 | U30: {=MEDIAN(IF('DEP2.H'!$E$2:$E$1001="00",'DEP2.H'!Z2:Z1001))} -> 0.5753677
A31: random | B31: random | C31: =C15 -> 244 | D31: 0 | E31: 0 | F31: 0 | G31: {=MEDIAN(IF(random!$E$2:$E$1001="00",random!H2:H1001))} -> 0.083244137 | I31: =COUNTIFS(random!O2:O1001,100,random!$E$2:$E$1001,"00")/$C$31 -> 0.44262295 | J31: =COUNTIFS(random!P2:P1001,100,random!$E$2:$E$1001,"00")/$C$31 -> 0.45491803 | K31: =COUNTIFS(random!Q2:Q1001,100,random!$E$2:$E$1001,"00")/$C$31 -> 0.50409836 | L31: =COUNTIFS(random!R2:R1001,100,random!$E$2:$E$1001,"00")/$C$31 -> 0.52459016 | M31: =COUNTIFS(random!S2:S1001,100,random!$E$2:$E$1001,"00")/$C$31 -> 0.58606557 | N31: =COUNTIFS(random!T2:T1001,100,random!$E$2:$E$1001,"00")/$C$31 -> 0.52459016 | P31: {=MEDIAN(IF(random!$E$2:$E$1001="00",random!U2:U1001))} -> 0.70319752 | Q31: {=MEDIAN(IF(random!$E$2:$E$1001="00",random!V2:V1001))} -> 0.69314718 | R31: {=MEDIAN(IF(random!$E$2:$E$1001="00",random!W2:W1001))} -> 0.69015217 | S31: {=MEDIAN(IF(random!$E$2:$E$1001="00",random!X2:X1001))} -> 0.68418793 | T31: {=MEDIAN(IF(random!$E$2:$E$1001="00",random!Y2:Y1001))} -> 0.68716511 | U31: {=MEDIAN(IF(random!$E$2:$E$1001="00",random!Z2:Z1001))} -> 0.68915516
A33: TRUE STATE OF TEST TAXON: 01
A34: scenario | B34: matrix | C34: test.00 | D34: test.01 | E34: test.10 | F34: test.11 | G34: terminal.std.med | I34: acc.bb | J34: acc.nb | K34: acc.ind | L34: acc.dep | M34: acc.ind.rj | N34: acc.dep.rj | P34: mll.bb | Q34: mll.nb | R34: mll.ind | S34: mll.dep | T34: mll.ind.rj | U34: mll.dep.rj
A35: ER.L | B35: Q1 | C35: 0 | D35: =D3 -> 195 | E35: 0 | F35: 0 | G35: {=MEDIAN(IF(ER.L!$E$2:$E$1001="01",ER.L!H2:H1001))} -> 0.067993281 | I35: =COUNTIFS(ER.L!O2:O1001,100,ER.L!$E$2:$E$1001,"01")/$D$35 -> 0.34871795 | J35: =COUNTIFS(ER.L!P2:P1001,100,ER.L!$E$2:$E$1001,"01")/$D$35 -> 0.37948718 | K35: =COUNTIFS(ER.L!Q2:Q1001,100,ER.L!$E$2:$E$1001,"01")/$D$35 -> 0.85641026 | L35: =COUNTIFS(ER.L!R2:R1001,100,ER.L!$E$2:$E$1001,"01")/$D$35 -> 0.84615385 | M35: =COUNTIFS(ER.L!S2:S1001,100,ER.L!$E$2:$E$1001,"01")/$D$35 -> 0.87179487 | N35: =COUNTIFS(ER.L!T2:T1001,100,ER.L!$E$2:$E$1001,"01")/$D$35 -> 0.86666667 | P35: {=MEDIAN(IF(ER.L!$E$2:$E$1001="01",ER.L!U2:U1001))} -> 0.83701755 | Q35: {=MEDIAN(IF(ER.L!$E$2:$E$1001="01",ER.L!V2:V1001))} -> 0.80349524 | R35: {=MEDIAN(IF(ER.L!$E$2:$E$1001="01",ER.L!W2:W1001))} -> 0.10981487 | S35: {=MEDIAN(IF(ER.L!$E$2:$E$1001="01",ER.L!X2:X1001))} -> 0.12669765 | T35: {=MEDIAN(IF(ER.L!$E$2:$E$1001="01",ER.L!Y2:Y1001))} -> 0.07364654 | U35: {=MEDIAN(IF(ER.L!$E$2:$E$1001="01",ER.L!Z2:Z1001))} -> 0.066139803
A36: ER.M | B36: Q2 | C36: 0 | D36: =D4 -> 264 | E36: 0 | F36: 0 | G36: {=MEDIAN(IF(ER.M!$E$2:$E$1001="01",ER.M!H2:H1001))} -> 0.081380473 | I36: =COUNTIFS(ER.M!O2:O1001,100,ER.M!$E$2:$E$1001,"01")/$D$36 -> 0.49242424 | J36: =COUNTIFS(ER.M!P2:P1001,100,ER.M!$E$2:$E$1001,"01")/$D$36 -> 0.4469697 | K36: =COUNTIFS(ER.M!Q2:Q1001,100,ER.M!$E$2:$E$1001,"01")/$D$36 -> 0.79924242 | L36: =COUNTIFS(ER.M!R2:R1001,100,ER.M!$E$2:$E$1001,"01")/$D$36 -> 0.76515152 | M36: =COUNTIFS(ER.M!S2:S1001,100,ER.M!$E$2:$E$1001,"01")/$D$36 -> 0.81060606 | N36: =COUNTIFS(ER.M!T2:T1001,100,ER.M!$E$2:$E$1001,"01")/$D$36 -> 0.79545455 | P36: {=MEDIAN(IF(ER.M!$E$2:$E$1001="01",ER.M!U2:U1001))} -> 0.69314718 | Q36: {=MEDIAN(IF(ER.M!$E$2:$E$1001="01",ER.M!V2:V1001))} -> 0.69314718 | R36: {=MEDIAN(IF(ER.M!$E$2:$E$1001="01",ER.M!W2:W1001))} -> 0.29236168 | S36: {=MEDIAN(IF(ER.M!$E$2:$E$1001="01",ER.M!X2:X1001))} -> 0.36169393 | T36: {=MEDIAN(IF(ER.M!$E$2:$E$1001="01",ER.M!Y2:Y1001))} -> 0.24654033 | U36: {=MEDIAN(IF(ER.M!$E$2:$E$1001="01",ER.M!Z2:Z1001))} -> 0.28105156
A37: ER.H | B37: Q3 | C37: 0 | D37: =D5 -> 265 | E37: 0 | F37: 0 | G37: {=MEDIAN(IF(ER.H!$E$2:$E$1001="01",ER.H!H2:H1001))} -> 0.084017494 | I37: =COUNTIFS(ER.H!O2:O1001,100,ER.H!$E$2:$E$1001,"01")/$D$37 -> 0.5245283 | J37: =COUNTIFS(ER.H!P2:P1001,100,ER.H!$E$2:$E$1001,"01")/$D$37 -> 0.49433962 | K37: =COUNTIFS(ER.H!Q2:Q1001,100,ER.H!$E$2:$E$1001,"01")/$D$37 -> 0.71320755 | L37: =COUNTIFS(ER.H!R2:R1001,100,ER.H!$E$2:$E$1001,"01")/$D$37 -> 0.68301887 | M37: =COUNTIFS(ER.H!S2:S1001,100,ER.H!$E$2:$E$1001,"01")/$D$37 -> 0.71698113 | N37: =COUNTIFS(ER.H!T2:T1001,100,ER.H!$E$2:$E$1001,"01")/$D$37 -> 0.67924528 | P37: {=MEDIAN(IF(ER.H!$E$2:$E$1001="01",ER.H!U2:U1001))} -> 0.68319685 | Q37: {=MEDIAN(IF(ER.H!$E$2:$E$1001="01",ER.H!V2:V1001))} -> 0.69314718 | R37: {=MEDIAN(IF(ER.H!$E$2:$E$1001="01",ER.H!W2:W1001))} -> 0.56563386 | S37: {=MEDIAN(IF(ER.H!$E$2:$E$1001="01",ER.H!X2:X1001))} -> 0.55164762 | T37: {=MEDIAN(IF(ER.H!$E$2:$E$1001="01",ER.H!Y2:Y1001))} -> 0.58160581 | U37: {=MEDIAN(IF(ER.H!$E$2:$E$1001="01",ER.H!Z2:Z1001))} -> 0.54300452
A38: DR.LM | B38: Q4 | C38: 0 | D38: =D6 -> 310 | E38: 0 | F38: 0 | G38: {=MEDIAN(IF(DR.LM!$E$2:$E$1001="01",DR.LM!H2:H1001))} -> 0.088804671 | I38: =COUNTIFS(DR.LM!O2:O1001,100,DR.LM!$E$2:$E$1001,"01")/$D$38 -> 0.91290323 | J38: =COUNTIFS(DR.LM!P2:P1001,100,DR.LM!$E$2:$E$1001,"01")/$D$38 -> 0.85483871 | K38: =COUNTIFS(DR.LM!Q2:Q1001,100,DR.LM!$E$2:$E$1001,"01")/$D$38 -> 0.90322581 | L38: =COUNTIFS(DR.LM!R2:R1001,100,DR.LM!$E$2:$E$1001,"01")/$D$38 -> 0.91935484 | M38: =COUNTIFS(DR.LM!S2:S1001,100,DR.LM!$E$2:$E$1001,"01")/$D$38 -> 0.89677419 | N38: =COUNTIFS(DR.LM!T2:T1001,100,DR.LM!$E$2:$E$1001,"01")/$D$38 -> 0.90645161 | P38: {=MEDIAN(IF(DR.LM!$E$2:$E$1001="01",DR.LM!U2:U1001))} -> 0.40571542 | Q38: {=MEDIAN(IF(DR.LM!$E$2:$E$1001="01",DR.LM!V2:V1001))} -> 0.37729423 | R38: {=MEDIAN(IF(DR.LM!$E$2:$E$1001="01",DR.LM!W2:W1001))} -> 0.11428915 | S38: {=MEDIAN(IF(DR.LM!$E$2:$E$1001="01",DR.LM!X2:X1001))} -> 0.13410315 | T38: {=MEDIAN(IF(DR.LM!$E$2:$E$1001="01",DR.LM!Y2:Y1001))} -> 0.10647224 | U38: {=MEDIAN(IF(DR.LM!$E$2:$E$1001="01",DR.LM!Z2:Z1001))} -> 0.086647807
A39: DR.LH | B39: Q5 | C39: 0 | D39: =D7 -> 407 | E39: 0 | F39: 0 | G39: {=MEDIAN(IF(DR.LH!$E$2:$E$1001="01",DR.LH!H2:H1001))} -> 0.091307818 | I39: =COUNTIFS(DR.LH!O2:O1001,100,DR.LH!$E$2:$E$1001,"01")/$D$39 -> 1 | J39: =COUNTIFS(DR.LH!P2:P1001,100,DR.LH!$E$2:$E$1001,"01")/$D$39 -> 0.98525799 | K39: =COUNTIFS(DR.LH!Q2:Q1001,100,DR.LH!$E$2:$E$1001,"01")/$D$39 -> 0.98280098 | L39: =COUNTIFS(DR.LH!R2:R1001,100,DR.LH!$E$2:$E$1001,"01")/$D$39 -> 0.98034398 | M39: =COUNTIFS(DR.LH!S2:S1001,100,DR.LH!$E$2:$E$1001,"01")/$D$39 -> 0.97297297 | N39: =COUNTIFS(DR.LH!T2:T1001,100,DR.LH!$E$2:$E$1001,"01")/$D$39 -> 0.96314496 | P39: {=MEDIAN(IF(DR.LH!$E$2:$E$1001="01",DR.LH!U2:U1001))} -> 0.19723217 | Q39: {=MEDIAN(IF(DR.LH!$E$2:$E$1001="01",DR.LH!V2:V1001))} -> 0.16251893 | R39: {=MEDIAN(IF(DR.LH!$E$2:$E$1001="01",DR.LH!W2:W1001))} -> 0.10092592 | S39: {=MEDIAN(IF(DR.LH!$E$2:$E$1001="01",DR.LH!X2:X1001))} -> 0.12216763 | T39: {=MEDIAN(IF(DR.LH!$E$2:$E$1001="01",DR.LH!Y2:Y1001))} -> 0.094310679 | U39: {=MEDIAN(IF(DR.LH!$E$2:$E$1001="01",DR.LH!Z2:Z1001))} -> 0.097612829
A40: DR.MH | B40: Q6 | C40: 0 | D40: =D8 -> 317 | E40: 0 | F40: 0 | G40: {=MEDIAN(IF(DR.MH!$E$2:$E$1001="01",DR.MH!H2:H1001))} -> 0.077807751 | I40: =COUNTIFS(DR.MH!O2:O1001,100,DR.MH!$E$2:$E$1001,"01")/$D$40 -> 0.9873817 | J40: =COUNTIFS(DR.MH!P2:P1001,100,DR.MH!$E$2:$E$1001,"01")/$D$40 -> 0.92429022 | K40: =COUNTIFS(DR.MH!Q2:Q1001,100,DR.MH!$E$2:$E$1001,"01")/$D$40 -> 0.89589905 | L40: =COUNTIFS(DR.MH!R2:R1001,100,DR.MH!$E$2:$E$1001,"01")/$D$40 -> 0.9022082 | M40: =COUNTIFS(DR.MH!S2:S1001,100,DR.MH!$E$2:$E$1001,"01")/$D$40 -> 0.85804416 | N40: =COUNTIFS(DR.MH!T2:T1001,100,DR.MH!$E$2:$E$1001,"01")/$D$40 -> 0.80126183 | P40: {=MEDIAN(IF(DR.MH!$E$2:$E$1001="01",DR.MH!U2:U1001))} -> 0.41551544 | Q40: {=MEDIAN(IF(DR.MH!$E$2:$E$1001="01",DR.MH!V2:V1001))} -> 0.42488319 | R40: {=MEDIAN(IF(DR.MH!$E$2:$E$1001="01",DR.MH!W2:W1001))} -> 0.26918749 | S40: {=MEDIAN(IF(DR.MH!$E$2:$E$1001="01",DR.MH!X2:X1001))} -> 0.31608155 | T40: {=MEDIAN(IF(DR.MH!$E$2:$E$1001="01",DR.MH!Y2:Y1001))} -> 0.25102875 | U40: {=MEDIAN(IF(DR.MH!$E$2:$E$1001="01",DR.MH!Z2:Z1001))} -> 0.27443685
A41: DEP1.L | B41: Q7 | C41: 0 | D41: =D9 -> 166 | E41: 0 | F41: 0 | G41: {=MEDIAN(IF('DEP1.L'!$E$2:$E$1001="01",'DEP1.L'!H2:H1001))} -> 0.090881829 | I41: =COUNTIFS('DEP1.L'!O2:O1001,100,'DEP1.L'!$E$2:$E$1001,"01")/$D$41 -> 0.46987952 | J41: =COUNTIFS('DEP1.L'!P2:P1001,100,'DEP1.L'!$E$2:$E$1001,"01")/$D$41 -> 0.3373494 | K41: =COUNTIFS('DEP1.L'!Q2:Q1001,100,'DEP1.L'!$E$2:$E$1001,"01")/$D$41 -> 0.77710843 | L41: =COUNTIFS('DEP1.L'!R2:R1001,100,'DEP1.L'!$E$2:$E$1001,"01")/$D$41 -> 0.75903614 | M41: =COUNTIFS('DEP1.L'!S2:S1001,100,'DEP1.L'!$E$2:$E$1001,"01")/$D$41 -> 0.77710843 | N41: =COUNTIFS('DEP1.L'!T2:T1001,100,'DEP1.L'!$E$2:$E$1001,"01")/$D$41 -> 0.77710843 | P41: {=MEDIAN(IF('DEP1.L'!$E$2:$E$1001="01",'DEP1.L'!U2:U1001))} -> 0.70927863 | Q41: {=MEDIAN(IF('DEP1.L'!$E$2:$E$1001="01",'DEP1.L'!V2:V1001))} -> 0.84308733 | R41: {=MEDIAN(IF('DEP1.L'!$E$2:$E$1001="01",'DEP1.L'!W2:W1001))} -> 0.16547297 | S41: {=MEDIAN(IF('DEP1.L'!$E$2:$E$1001="01",'DEP1.L'!X2:X1001))} -> 0.19784601 | T41: {=MEDIAN(IF('DEP1.L'!$E$2:$E$1001="01",'DEP1.L'!Y2:Y1001))} -> 0.1266983 | U41: {=MEDIAN(IF('DEP1.L'!$E$2:$E$1001="01",'DEP1.L'!Z2:Z1001))} -> 0.17258356
A42: DEP1.M | B42: Q8 | C42: 0 | D42: =D10 -> 232 | E42: 0 | F42: 0 | G42: {=MEDIAN(IF('DEP1.M'!$E$2:$E$1001="01",'DEP1.M'!H2:H1001))} -> 0.085042433 | I42: =COUNTIFS('DEP1.M'!O2:O1001,100,'DEP1.M'!$E$2:$E$1001,"01")/$D$42 -> 0.75862069 | J42: =COUNTIFS('DEP1.M'!P2:P1001,100,'DEP1.M'!$E$2:$E$1001,"01")/$D$42 -> 0.4612069 | K42: =COUNTIFS('DEP1.M'!Q2:Q1001,100,'DEP1.M'!$E$2:$E$1001,"01")/$D$42 -> 0.84913793 | L42: =COUNTIFS('DEP1.M'!R2:R1001,100,'DEP1.M'!$E$2:$E$1001,"01")/$D$42 -> 0.67672414 | M42: =COUNTIFS('DEP1.M'!S2:S1001,100,'DEP1.M'!$E$2:$E$1001,"01")/$D$42 -> 0.82758621 | N42: =COUNTIFS('DEP1.M'!T2:T1001,100,'DEP1.M'!$E$2:$E$1001,"01")/$D$42 -> 0.74568966 | P42: {=MEDIAN(IF('DEP1.M'!$E$2:$E$1001="01",'DEP1.M'!U2:U1001))} -> 0.55686956 | Q42: {=MEDIAN(IF('DEP1.M'!$E$2:$E$1001="01",'DEP1.M'!V2:V1001))} -> 0.71522207 | R42: {=MEDIAN(IF('DEP1.M'!$E$2:$E$1001="01",'DEP1.M'!W2:W1001))} -> 0.28236291 | S42: {=MEDIAN(IF('DEP1.M'!$E$2:$E$1001="01",'DEP1.M'!X2:X1001))} -> 0.39749805 | T42: {=MEDIAN(IF('DEP1.M'!$E$2:$E$1001="01",'DEP1.M'!Y2:Y1001))} -> 0.26461701 | U42: {=MEDIAN(IF('DEP1.M'!$E$2:$E$1001="01",'DEP1.M'!Z2:Z1001))} -> 0.35240749
...

Sheet ER.L
A1: trial | B1: taxon | C1: x | D1: y | E1: xy | F1: terminal | G1: height | H1: terminal.std | I1: p.bb | J1: p.nb | K1: p.ind.b | L1: p.dep.b | M1: p.ind.rj | N1: p.dep.rj | O1: c.bb | P1: c.nb | Q1: c.ind.b | R1: c.dep.b | S1: c.ind.rj | T1: c.dep.rj | U1: ll.bb | V1: ll.nb | W1: ll.ind.b | X1: ll.dep.b | Y1: ll.ind.rj | Z1: ll.dep.rj
A2: 855 | B2: 47 | C2: 0 | D2: 0 | E2: =_xlfn.CONCAT(C2,D2) -> 00 | F2: 0.0023719153 | G2: 31.816479 | H2: =F2/G2 -> 7.4549898e-05 | I2: 0.281 | J2: 0.27272727 | K2: 0.001 | L2: 0.001 | M2: 0.001 | N2: 0 | O2: 100 | P2: 100 | Q2: 100 | R2: 100 | S2: 100 | T2: 100 | U2: 0.32989392 | V2: 0.31845373 | W2: 0.0010005003 | X2: 0.0010005003 | Y2: 0.0010005003 | Z2: 1.000005e-05
A3: 921 | B3: 29 | C3: 0 | D3: 0 | E3: =_xlfn.CONCAT(C3,D3) -> 00 | F3: 0.0045319638 | G3: 26.011342 | H3: =F3/G3 -> 0.00017423029 | I3: 0.201 | J3: 0.23188406 | K3: 0 | L3: 0 | M3: 0 | N3: 0 | O3: 100 | P3: 100 | Q3: 100 | R3: 100 | S3: 100 | T3: 100 | U3: 0.22439433 | V3: 0.26381459 | W3: 1.000005e-05 | X3: 1.000005e-05 | Y3: 1.000005e-05 | Z3: 1.000005e-05
A4: 651 | B4: 88 | C4: 0 | D4: 0 | E4: =_xlfn.CONCAT(C4,D4) -> 00 | F4: 0.01910717 | G4: 25.279355 | H4: =F4/G4 -> 0.0007558409 | I4: 0.408 | J4: 0.43037975 | K4: 0 | L4: 0 | M4: 0 | N4: 0 | O4: 100 | P4: 100 | Q4: 100 | R4: 100 | S4: 100 | T4: 100 | U4: 0.52424864 | V4: 0.56278536 | W4: 1.000005e-05 | X4: 1.000005e-05 | Y4: 1.000005e-05 | Z4: 1.000005e-05
A5: 425 | B5: 31 | C5: 0 | D5: 0 | E5: =_xlfn.CONCAT(C5,D5) -> 00 | F5: 0.021055937 | G5: 25.093414 | H5: =F5/G5 -> 0.00083910211 | I5: 0.321 | J5: 0.28571429 | K5: 0 | L5: 0 | M5: 0 | N5: 0 | O5: 100 | P5: 100 | Q5: 100 | R5: 100 | S5: 100 | T5: 100 | U5: 0.38713415 | V5: 0.33647224 | W5: 1.000005e-05 | X5: 1.000005e-05 | Y5: 1.000005e-05 | Z5: 1.000005e-05
A6: 295 | B6: 75 | C6: 0 | D6: 0 | E6: =_xlfn.CONCAT(C6,D6) -> 00 | F6: 0.028489165 | G6: 27.147045 | H6: =F6/G6 -> 0.0010494389 | I6: 0.134 | J6: 0.19047619 | K6: 0 | L6: 0 | M6: 0 | N6: 0.001 | O6: 100 | P6: 100 | Q6: 100 | R6: 100 | S6: 100 | T6: 100 | U6: 0.14387037 | V6: 0.21130909 | W6: 1.000005e-05 | X6: 1.000005e-05 | Y6: 1.000005e-05 | Z6: 0.0010005003
A7: 63 | B7: 62 | C7: 0 | D7: 0 | E7: =_xlfn.CONCAT(C7,D7) -> 00 | F7: 0.04567293 | G7: 30.850488 | H7: =F7/G7 -> 0.0014804605 | I7: 0.131 | J7: 0.17391304 | K7: 0.002 | L7: 0 | M7: 0.002 | N7: 0.001 | O7: 100 | P7: 100 | Q7: 100 | R7: 100 | S7: 100 | T7: 100 | U7: 0.14041215 | V7: 0.19105524 | W7: 0.0020020027 | X7: 1.000005e-05 | Y7: 0.0020020027 | Z7: 0.0010005003
A8: 403 | B8: 46 | C8: 0 | D8: 0 | E8: =_xlfn.CONCAT(C8,D8) -> 00 | F8: 0.043587619 | G8: 29.28151 | H8: =F8/G8 -> 0.0014885714 | I8: 0.367 | J8: 0.30136986 | K8: 0.004 | L8: 0 | M8: 0.002 | N8: 0.001 | O8: 100 | P8: 100 | Q8: 100 | R8: 100 | S8: 100 | T8: 100 | U8: 0.45728486 | V8: 0.35863381 | W8: 0.0040080214 | X8: 1.000005e-05 | Y8: 0.0020020027 | Z8: 0.0010005003
A9: 619 | B9: 81 | C9: 0 | D9: 0 | E9: =_xlfn.CONCAT(C9,D9) -> 00 | F9: 0.059106745 | G9: 36.413223 | H9: =F9/G9 -> 0.001623222 | I9: 0.271 | J9: 0.17857143 | K9: 0.001 | L9: 0.051 | M9: 0.003 | N9: 0.004 | O9: 100 | P9: 100 | Q9: 100 | R9: 100 | S9: 100 | T9: 100 | U9: 0.31608155 | V9: 0.19671029 | W9: 0.0010005003 | X9: 0.05234648 | Y9: 0.003004509 | Z9: 0.0040080214
A10: 589 | B10: 2 | C10: 0 | D10: 0 | E10: =_xlfn.CONCAT(C10,D10) -> 00 | F10: 0.065587221 | G10: 32.487462 | H10: =F10/G10 -> 0.0020188472 | I10: 0.288 | J10: 0.25 | K10: 0.001 | L10: 0.001 | M10: 0.001 | N10: 0.001 | O10: 100 | P10: 100 | Q10: 100 | R10: 100 | S10: 100 | T10: 100 | U10: 0.33967737 | V10: 0.28768207 | W10: 0.0010005003 | X10: 0.0010005003 | Y10: 0.0010005003 | Z10: 0.0010005003
A11: 269 | B11: 17 | C11: 0 | D11: 0 | E11: =_xlfn.CONCAT(C11,D11) -> 00 | F11: 0.059058583 | G11: 25.606691 | H11: =F11/G11 -> 0.002306373 | I11: 0.401 | J11: 0.36708861 | K11: 0.003 | L11: 0.001 | M11: 0.002 | N11: 0 | O11: 100 | P11: 100 | Q11: 100 | R11: 100 | S11: 100 | T11: 100 | U11: 0.51249368 | V11: 0.45742485 | W11: 0.003004509 | X11: 0.0010005003 | Y11: 0.0020020027 | Z11: 1.000005e-05
A12: 357 | B12: 92 | C12: 0 | D12: 0 | E12: =_xlfn.CONCAT(C12,D12) -> 00 | F12: 0.075635665 | G12: 29.70223 | H12: =F12/G12 -> 0.0025464642 | I12: 0.296 | J12: 0.30188679 | K12: 0.001 | L12: 0.004 | M12: 0.002 | N12: 0.005 | O12: 100 | P12: 100 | Q12: 100 | R12: 100 | S12: 100 | T12: 100 | U12: 0.35097692 | V12: 0.359374 | W12: 0.0010005003 | X12: 0.0040080214 | Y12: 0.0020020027 | Z12: 0.0050125418
A13: 137 | B13: 1 | C13: 0 | D13: 0 | E13: =_xlfn.CONCAT(C13,D13) -> 00 | F13: 0.073285223 | G13: 20.891452 | H13: =F13/G13 -> 0.0035079046 | I13: 0.382 | J13: 0.28358209 | K13: 0 | L13: 0.001 | M13: 0.004 | N13: 0.002 | O13: 100 | P13: 100 | Q13: 100 | R13: 100 | S13: 100 | T13: 100 | U13: 0.48126682 | V13: 0.33349161 | W13: 1.000005e-05 | X13: 0.0010005003 | Y13: 0.0040080214 | Z13: 0.0020020027
... A1001: 6 | B1001: 21 | C1001: 1 | D1001: 1 | E1001: =_xlfn.CONCAT(C1001,D1001) -> 11 | F1001: 19.783078 | G1001: 26.218072 | H1001: =F1001/G1001 -> 0.75455881 | I1001: 0.132 | J1001: 0.057142857 | K1001: 0.138 | L1001: 0.043 | M1001: 0.152 | N1001: 0.079 | O1001: 0 | P1001: 0 | Q1001: 0 | R1001: 0 | S1001: 0 | T1001: 0 | U1001: 2.0249534 | V1001: 2.8622009 | W1001: 1.9805016 | X1001: 3.1465552 | Y1001: 1.8838748 | Z1001: 2.5383074

Sheet ER.M
A1: trial | B1: taxon | C1: x | D1: y | E1: xy | F1: terminal | G1: height | H1: terminal.std | I1: p.bb | J1: p.nb | K1: p.ind.b | L1: p.dep.b | M1: p.ind.rj | N1: p.dep.rj | O1: c.bb | P1: c.nb | Q1: c.ind.b | R1: c.dep.b | S1: c.ind.rj | T1: c.dep.rj | U1: ll.bb | V1: ll.nb | W1: ll.ind.b | X1: ll.dep.b | Y1: ll.ind.rj | Z1: ll.dep.rj
A2: 811 | B2: 94 | C2: 0 | D2: 0 | E2: =_xlfn.CONCAT(C2,D2) -> 00 | F2: 0.0013172775 | G2: 38.649754 | H2: =F2/G2 -> 3.408243e-05 | I2: 0.469 | J2: 0.53448276 | K2: 0 | L2: 0 | M2: 0 | N2: 0 | O2: 100 | P2: 0 | Q2: 100 | R2: 100 | S2: 100 | T2: 100 | U2: 0.63299326 | V2: 0.76460614 | W2: 1.000005e-05 | X2: 1.000005e-05 | Y2: 1.000005e-05 | Z2: 1.000005e-05
A3: 291 | B3: 14 | C3: 0 | D3: 0 | E3: =_xlfn.CONCAT(C3,D3) -> 00 | F3: 0.028477796 | G3: 29.564687 | H3: =F3/G3 -> 0.00096323685 | I3: 0.461 | J3: 0.5 | K3: 0.003 | L3: 0.004 | M3: 0.002 | N3: 0.003 | O3: 100 | P3: 0 | Q3: 100 | R3: 100 | S3: 100 | T3: 100 | U3: 0.61803971 | V3: 0.69314718 | W3: 0.003004509 | X3: 0.0040080214 | Y3: 0.0020020027 | Z3: 0.003004509
A4: 169 | B4: 75 | C4: 0 | D4: 0 | E4: =_xlfn.CONCAT(C4,D4) -> 00 | F4: 0.054753185 | G4: 24.574409 | H4: =F4/G4 -> 0.002228057 | I4: 0.328 | J4: 0.25531915 | K4: 0.003 | L4: 0.003 | M4: 0.006 | N4: 0 | O4: 100 | P4: 100 | Q4: 100 | R4: 100 | S4: 100 | T4: 100 | U4: 0.39749694 | V4: 0.29479954 | W4: 0.003004509 | X4: 0.003004509 | Y4: 0.0060180723 | Z4: 1.000005e-05
A5: 255 | B5: 39 | C5: 0 | D5: 0 | E5: =_xlfn.CONCAT(C5,D5) -> 00 | F5: 0.15652631 | G5: 32.615511 | H5: =F5/G5 -> 0.0047991373 | I5: 0.374 | J5: 0.35897436 | K5: 0.005 | L5: 0.015 | M5: 0.009 | N5: 0.025 | O5: 100 | P5: 100 | Q5: 100 | R5: 100 | S5: 100 | T5: 100 | U5: 0.46840491 | V5: 0.44468582 | W5: 0.0050125418 | X5: 0.015113638 | Y5: 0.0090407447 | Z5: 0.025317808
A6: 897 | B6: 45 | C6: 0 | D6: 0 | E6: =_xlfn.CONCAT(C6,D6) -> 00 | F6: 0.13818406 | G6: 28.613857 | H6: =F6/G6 -> 0.0048292708 | I6: 0.453 | J6: 0.58333333 | K6: 0.019 | L6: 0.014 | M6: 0.017 | N6: 0.017 | O6: 100 | P6: 0 | Q6: 100 | R6: 100 | S6: 100 | T6: 100 | U6: 0.60330648 | V6: 0.87546874 | W6: 0.019182819 | X6: 0.014098924 | Y6: 0.017146159 | Z6: 0.017146159
A7: 71 | B7: 97 | C7: 0 | D7: 0 | E7: =_xlfn.CONCAT(C7,D7) -> 00 | F7: 0.13343366 | G7: 25.41962 | H7: =F7/G7 -> 0.0052492389 | I7: 0.434 | J7: 0.43636364 | K7: 0.023 | L7: 0.007 | M7: 0.014 | N7: 0.02 | O7: 100 | P7: 100 | Q7: 100 | R7: 100 | S7: 100 | T7: 100 | U7: 0.5691612 | V7: 0.57334598 | W7: 0.023268627 | X7: 0.0070246149 | Y7: 0.014098924 | Z7: 0.020202707
A8: 433 | B8: 90 | C8: 0 | D8: 0 | E8: =_xlfn.CONCAT(C8,D8) -> 00 | F8: 0.16701016 | G8: 30.843167 | H8: =F8/G8 -> 0.0054148189 | I8: 0.513 | J8: 0.43181818 | K8: 0.03 | L8: 0.008 | M8: 0.028 | N8: 0 | O8: 0 | P8: 100 | Q8: 100 | R8: 100 | S8: 100 | T8: 100 | U8: 0.71949116 | V8: 0.56531381 | W8: 0.030459207 | X8: 0.0080321717 | Y8: 0.028399475 | Z8: 1.000005e-05
A9: 313 | B9: 97 | C9: 0 | D9: 0 | E9: =_xlfn.CONCAT(C9,D9) -> 00 | F9: 0.21908932 | G9: 39.497567 | H9: =F9/G9 -> 0.0055469068 | I9: 0.568 | J9: 0.7755102 | K9: 0.055 | L9: 0.161 | M9: 0.039 | N9: 0.097 | O9: 0 | P9: 0 | Q9: 100 | R9: 100 | S9: 100 | T9: 100 | U9: 0.83932969 | V9: 1.493925 | W9: 0.056570351 | X9: 0.17554457 | Y9: 0.03978087 | Z9: 0.10203273
A10: 623 | B10: 37 | C10: 0 | D10: 0 | E10: =_xlfn.CONCAT(C10,D10) -> 00 | F10: 0.25202013 | G10: 35.139309 | H10: =F10/G10 -> 0.0071720286 | I10: 0.466 | J10: 0.55555556 | K10: 0.026 | L10: 0.054 | M10: 0.033 | N10: 0.024 | O10: 100 | P10: 0 | Q10: 100 | R10: 100 | S10: 100 | T10: 100 | U10: 0.62735944 | V10: 0.81093022 | W10: 0.026343975 | X10: 0.05551271 | Y10: 0.033556784 | Z10: 0.024292693
A11: 815 | B11: 48 | C11: 0 | D11: 0 | E11: =_xlfn.CONCAT(C11,D11) -> 00 | F11: 0.221909 | G11: 30.438062 | H11: =F11/G11 -> 0.0072905103 | I11: 0.46 | J11: 0.53488372 | K11: 0.074 | L11: 0.086 | M11: 0.032 | N11: 0.053 | O11: 100 | P11: 0 | Q11: 100 | R11: 100 | S11: 100 | T11: 100 | U11: 0.61618614 | V11: 0.76546784 | W11: 0.076881044 | X11: 0.089924708 | Y11: 0.032523192 | Z11: 0.054456186
A12: 697 | B12: 77 | C12: 0 | D12: 0 | E12: =_xlfn.CONCAT(C12,D12) -> 00 | F12: 0.24021386 | G12: 27.357649 | H12: =F12/G12 -> 0.0087805008 | I12: 0.578 | J12: 0.56756757 | K12: 0.029 | L12: 0.032 | M12: 0.034 | N12: 0.022 | O12: 0 | P12: 0 | Q12: 100 | R12: 100 | S12: 100 | T12: 100 | U12: 0.86274996 | V12: 0.83832919 | W12: 0.029428811 | X12: 0.032523192 | Y12: 0.034591445 | Z12: 0.022245609
A13: 345 | B13: 82 | C13: 0 | D13: 0 | E13: =_xlfn.CONCAT(C13,D13) -> 00 | F13: 0.31881357 | G13: 34.107635 | H13: =F13/G13 -> 0.0093472786 | I13: 0.469 | J13: 0.47368421 | K13: 0.276 | L13: 0.295 | M13: 0.285 | N13: 0.285 | O13: 100 | P13: 100 | Q13: 100 | R13: 100 | S13: 100 | T13: 100 | U13: 0.63299326 | V13: 0.64185389 | W13: 0.32296389 | X13: 0.34955748 | Y13: 0.33547274 | Z13: 0.33547274
... A1001: 592 | B1001: 78 | C1001: 1 | D1001: 1 | E1001: =_xlfn.CONCAT(C1001,D1001) -> 11 | F1001: 15.973769 | G1001: 26.675776 | H1001: =F1001/G1001 -> 0.59881177 | I1001: 0.63 | J1001: 0.60714286 | K1001: 0.575 | L1001: 0.608 | M1001: 0.496 | N1001: 0.498 | O1001: 100 | P1001: 100 | Q1001: 100 | R1001: 100 | S1001: 0 | T1001: 0 | U1001: 0.46203546 | V1001: 0.49899117 | W1001: 0.55338524 | X1001: 0.4975804 | Y1001: 0.70117935 | Z1001: 0.6971552

Sheet ER.H
A1: trial | B1: taxon | C1: x | D1: y | E1: xy | F1: terminal | G1: height | H1: terminal.std | I1: p.bb | J1: p.nb | K1: p.ind.b | L1: p.dep.b | M1: p.ind.rj | N1: p.dep.rj | O1: c.bb | P1: c.nb | Q1: c.ind.b | R1: c.dep.b | S1: c.ind.rj | T1: c.dep.rj | U1: ll.bb | V1: ll.nb | W1: ll.ind.b | X1: ll.dep.b | Y1: ll.ind.rj | Z1: ll.dep.rj
A2: 25 | B2: 92 | C2: 0 | D2: 0 | E2: =_xlfn.CONCAT(C2,D2) -> 00 | F2: 0.079358275 | G2: 43.063355 | H2: =F2/G2 -> 0.0018428261 | I2: 0.526 | J2: 0.41509434 | K2: 0.01 | L2: 0.013 | M2: 0.007 | N2: 0.008 | O2: 0 | P2: 100 | Q2: 100 | R2: 100 | S2: 100 | T2: 100 | U2: 0.74654796 | V2: 0.53630471 | W2: 0.010050336 | X2: 0.01308524 | Y2: 0.0070246149 | Z2: 0.0080321717
A3: 301 | B3: 56 | C3: 0 | D3: 0 | E3: =_xlfn.CONCAT(C3,D3) -> 00 | F3: 0.076532401 | G3: 36.737888 | H3: =F3/G3 -> 0.0020832009 | I3: 0.496 | J3: 0.57142857 | K3: 0.024 | L3: 0.16 | M3: 0.022 | N3: 0.018 | O3: 100 | P3: 0 | Q3: 100 | R3: 100 | S3: 100 | T3: 100 | U3: 0.68517901 | V3: 0.84729786 | W3: 0.024292693 | X3: 0.17435339 | Y3: 0.022245609 | Z3: 0.018163971
A4: 79 | B4: 94 | C4: 0 | D4: 0 | E4: =_xlfn.CONCAT(C4,D4) -> 00 | F4: 0.060558665 | G4: 26.841268 | H4: =F4/G4 -> 0.0022561775 | I4: 0.484 | J4: 0.48979592 | K4: 0.059 | L4: 0.114 | M4: 0.024 | N4: 0.038 | O4: 100 | P4: 100 | Q4: 100 | R4: 100 | S4: 100 | T4: 100 | U4: 0.66164851 | V4: 0.67294447 | W4: 0.060812139 | X4: 0.12103833 | Y4: 0.024292693 | Z4: 0.038740828
A5: 531 | B5: 94 | C5: 0 | D5: 0 | E5: =_xlfn.CONCAT(C5,D5) -> 00 | F5: 0.061435769 | G5: 26.269854 | H5: =F5/G5 -> 0.0023386415 | I5: 0.497 | J5: 0.4047619 | K5: 0.013 | L5: 0.036 | M5: 0.007 | N5: 0.012 | O5: 100 | P5: 100 | Q5: 100 | R5: 100 | S5: 100 | T5: 100 | U5: 0.68716511 | V5: 0.51879379 | W5: 0.01308524 | X5: 0.036663984 | Y5: 0.0070246149 | Z5: 0.012072581
A6: 479 | B6: 57 | C6: 0 | D6: 0 | E6: =_xlfn.CONCAT(C6,D6) -> 00 | F6: 0.084026036 | G6: 32.20593 | H6: =F6/G6 -> 0.0026090237 | I6: 0.534 | J6: 0.45238095 | K6: 0.049 | L6: 0.133 | M6: 0.015 | N6: 0.023 | O6: 0 | P6: 100 | Q6: 100 | R6: 100 | S6: 100 | T6: 100 | U6: 0.76356964 | V6: 0.6021754 | W6: 0.050241216 | X6: 0.1427163 | Y6: 0.015113638 | Z6: 0.023268627
A7: 981 | B7: 44 | C7: 0 | D7: 0 | E7: =_xlfn.CONCAT(C7,D7) -> 00 | F7: 0.083354727 | G7: 30.205808 | H7: =F7/G7 -> 0.0027595596 | I7: 0.538 | J7: 0.4375 | K7: 0.033 | L7: 0.058 | M7: 0.026 | N7: 0.025 | O7: 0 | P7: 100 | Q7: 100 | R7: 100 | S7: 100 | T7: 100 | U7: 0.77219039 | V7: 0.57536414 | W7: 0.033556784 | X7: 0.059750004 | Y7: 0.026343975 | Z7: 0.025317808
A8: 333 | B8: 13 | C8: 0 | D8: 0 | E8: =_xlfn.CONCAT(C8,D8) -> 00 | F8: 0.085956574 | G8: 29.401696 | H8: =F8/G8 -> 0.0029235243 | I8: 0.454 | J8: 0.45098039 | K8: 0.083 | L8: 0.176 | M8: 0.039 | N8: 0.032 | O8: 100 | P8: 100 | Q8: 100 | R8: 100 | S8: 100 | T8: 100 | U8: 0.6051363 | V8: 0.59962112 | W8: 0.086647807 | X8: 0.19358475 | Y8: 0.03978087 | Z8: 0.032523192
A9: 589 | B9: 80 | C9: 0 | D9: 0 | E9: =_xlfn.CONCAT(C9,D9) -> 00 | F9: 0.12992861 | G9: 32.487462 | H9: =F9/G9 -> 0.0039993462 | I9: 0.494 | J9: 0.48 | K9: 0.035 | L9: 0.016 | M9: 0.044 | N9: 0.001 | O9: 100 | P9: 100 | Q9: 100 | R9: 100 | S9: 100 | T9: 100 | U9: 0.68121861 | V9: 0.65392647 | W9: 0.035627178 | X9: 0.016129382 | Y9: 0.044997366 | Z9: 0.0010005003
A10: 359 | B10: 11 | C10: 0 | D10: 0 | E10: =_xlfn.CONCAT(C10,D10) -> 00 | F10: 0.11561949 | G10: 28.590062 | H10: =F10/G10 -> 0.0040440447 | I10: 0.608 | J10: 0.65306122 | K10: 0.046 | L10: 0.07 | M10: 0.022 | N10: 0.022 | O10: 0 | P10: 0 | Q10: 100 | R10: 100 | S10: 100 | T10: 100 | U10: 0.93649344 | V10: 1.058607 | W10: 0.047091608 | X10: 0.072570693 | Y10: 0.022245609 | Z10: 0.022245609
A11: 605 | B11: 87 | C11: 0 | D11: 0 | E11: =_xlfn.CONCAT(C11,D11) -> 00 | F11: 0.14833743 | G11: 35.308815 | H11: =F11/G11 -> 0.0042011442 | I11: 0.444 | J11: 0.38 | K11: 0.026 | L11: 0.017 | M11: 0.013 | N11: 0.024 | O11: 100 | P11: 100 | Q11: 100 | R11: 100 | S11: 100 | T11: 100 | U11: 0.58698698 | V11: 0.4780358 | W11: 0.026343975 | X11: 0.017146159 | Y11: 0.01308524 | Z11: 0.024292693
A12: 837 | B12: 58 | C12: 0 | D12: 0 | E12: =_xlfn.CONCAT(C12,D12) -> 00 | F12: 0.12987715 | G12: 25.42121 | H12: =F12/G12 -> 0.0051090075 | I12: 0.459 | J12: 0.30952381 | K12: 0.013 | L12: 0.007 | M12: 0.017 | N12: 0.006 | O12: 100 | P12: 100 | Q12: 100 | R12: 100 | S12: 100 | T12: 100 | U12: 0.614336 | V12: 0.37037379 | W12: 0.01308524 | X12: 0.0070246149 | Y12: 0.017146159 | Z12: 0.0060180723
A13: 723 | B13: 3 | C13: 0 | D13: 0 | E13: =_xlfn.CONCAT(C13,D13) -> 00 | F13: 0.22663281 | G13: 38.72722 | H13: =F13/G13 -> 0.0058520288 | I13: 0.48 | J13: 0.5 | K13: 0.017 | L13: 0.02 | M13: 0.032 | N13: 0.003 | O13: 100 | P13: 0 | Q13: 100 | R13: 100 | S13: 100 | T13: 100 | U13: 0.65392647 | V13: 0.69314718 | W13: 0.017146159 | X13: 0.020202707 | Y13: 0.032523192 | Z13: 0.003004509
... A1001: 148 | B1001: 43 | C1001: 1 | D1001: 1 | E1001: =_xlfn.CONCAT(C1001,D1001) -> 11 | F1001: 22.044664 | G1001: 22.928208 | H1001: =F1001/G1001 -> 0.96146478 | I1001: 0.506 | J1001: 0.44230769 | K1001: 0.479 | L1001: 0.439 | M1001: 0.48 | N1001: 0.51 | O1001: 100 | P1001: 0 | Q1001: 0 | R1001: 0 | S1001: 0 | T1001: 100 | U1001: 0.68121861 | V1001: 0.8157495 | W1001: 0.73605468 | X1001: 0.82325587 | Y1001: 0.73396918 | Z1001: 0.67334455

Sheet DR.LM
A1: trial | B1: taxon | C1: x | D1: y | E1: xy | F1: terminal | G1: height | H1: terminal.std | I1: p.bb | J1: p.nb | K1: p.ind.b | L1: p.dep.b | M1: p.ind.rj | N1: p.dep.rj | O1: c.bb | P1: c.nb | Q1: c.ind.b | R1: c.dep.b | S1: c.ind.rj | T1: c.dep.rj | U1: ll.bb | V1: ll.nb | W1: ll.ind.b | X1: ll.dep.b | Y1: ll.ind.rj | Z1: ll.dep.rj
A2: 15 | B2: 99 | C2: 0 | D2: 0 | E2: =_xlfn.CONCAT(C2,D2) -> 00 | F2: 0.0060116075 | G2: 26.816165 | H2: =F2/G2 -> 0.00022417849 | I2: 0.505 | J2: 0.53191489 | K2: 0 | L2: 0.001 | M2: 0.001 | N2: 0 | O2: 0 | P2: 0 | Q2: 100 | R2: 100 | S2: 100 | T2: 100 | U2: 0.70319752 | V2: 0.75910515 | W2: 1.000005e-05 | X2: 0.0010005003 | Y2: 0.0010005003 | Z2: 1.000005e-05
A3: 875 | B3: 53 | C3: 0 | D3: 0 | E3: =_xlfn.CONCAT(C3,D3) -> 00 | F3: 0.0096674314 | G3: 28.421954 | H3: =F3/G3 -> 0.00034013957 | I3: 0.746 | J3: 0.79166667 | K3: 0 | L3: 0.006 | M3: 0.002 | N3: 0 | O3: 0 | P3: 0 | Q3: 100 | R3: 100 | S3: 100 | T3: 100 | U3: 1.370421 | V3: 1.5686159 | W3: 1.000005e-05 | X3: 0.0060180723 | Y3: 0.0020020027 | Z3: 1.000005e-05
A4: 213 | B4: 39 | C4: 0 | D4: 0 | E4: =_xlfn.CONCAT(C4,D4) -> 00 | F4: 0.018853231 | G4: 27.750611 | H4: =F4/G4 -> 0.00067938075 | I4: 0.627 | J4: 0.70731707 | K4: 0.003 | L4: 0.003 | M4: 0 | N4: 0 | O4: 0 | P4: 0 | Q4: 100 | R4: 100 | S4: 100 | T4: 100 | U4: 0.98617686 | V4: 1.2286654 | W4: 0.003004509 | X4: 0.003004509 | Y4: 1.000005e-05 | Z4: 1.000005e-05
A5: 109 | B5: 14 | C5: 0 | D5: 0 | E5: =_xlfn.CONCAT(C5,D5) -> 00 | F5: 0.026906312 | G5: 27.238355 | H5: =F5/G5 -> 0.00098780974 | I5: 0.683 | J5: 0.68965517 | K5: 0.005 | L5: 0.003 | M5: 0.001 | N5: 0.002 | O5: 0 | P5: 0 | Q5: 100 | R5: 100 | S5: 100 | T5: 100 | U5: 1.1488535 | V5: 1.1700713 | W5: 0.0050125418 | X5: 0.003004509 | Y5: 0.0010005003 | Z5: 0.0020020027
A6: 921 | B6: 82 | C6: 0 | D6: 0 | E6: =_xlfn.CONCAT(C6,D6) -> 00 | F6: 0.041452798 | G6: 26.011342 | H6: =F6/G6 -> 0.0015936432 | I6: 0.67 | J6: 0.66666667 | K6: 0.003 | L6: 0.006 | M6: 0 | N6: 0.002 | O6: 0 | P6: 0 | Q6: 100 | R6: 100 | S6: 100 | T6: 100 | U6: 1.1086626 | V6: 1.0986123 | W6: 0.003004509 | X6: 0.0060180723 | Y6: 1.000005e-05 | Z6: 0.0020020027
A7: 799 | B7: 98 | C7: 0 | D7: 0 | E7: =_xlfn.CONCAT(C7,D7) -> 00 | F7: 0.11178921 | G7: 31.638242 | H7: =F7/G7 -> 0.0035333572 | I7: 0.518 | J7: 0.71428571 | K7: 0.009 | L7: 0.008 | M7: 0.01 | N7: 0.007 | O7: 0 | P7: 0 | Q7: 100 | R7: 100 | S7: 100 | T7: 100 | U7: 0.72981116 | V7: 1.252763 | W7: 0.0090407447 | X7: 0.0080321717 | Y7: 0.010050336 | Z7: 0.0070246149
A8: 73 | B8: 5 | C8: 0 | D8: 0 | E8: =_xlfn.CONCAT(C8,D8) -> 00 | F8: 0.18239864 | G8: 49.855361 | H8: =F8/G8 -> 0.0036585562 | I8: 0.554 | J8: 0.65909091 | K8: 0.015 | L8: 0.018 | M8: 0.006 | N8: 0.011 | O8: 0 | P8: 0 | Q8: 100 | R8: 100 | S8: 100 | T8: 100 | U8: 0.80743633 | V8: 1.0761394 | W8: 0.015113638 | X8: 0.018163971 | Y8: 0.0060180723 | Z8: 0.011060947
A9: 619 | B9: 58 | C9: 0 | D9: 0 | E9: =_xlfn.CONCAT(C9,D9) -> 00 | F9: 0.13386176 | G9: 36.413223 | H9: =F9/G9 -> 0.0036761853 | I9: 0.695 | J9: 0.8 | K9: 0.026 | L9: 0.443 | M9: 0.019 | N9: 0.024 | O9: 0 | P9: 0 | Q9: 100 | R9: 100 | S9: 100 | T9: 100 | U9: 1.1874435 | V9: 1.6094379 | W9: 0.026343975 | X9: 0.58519004 | Y9: 0.019182819 | Z9: 0.024292693
A10: 431 | B10: 54 | C10: 0 | D10: 0 | E10: =_xlfn.CONCAT(C10,D10) -> 00 | F10: 0.14236584 | G10: 29.628831 | H10: =F10/G10 -> 0.0048049765 | I10: 0.696 | J10: 0.6875 | K10: 0.071 | L10: 0.066 | M10: 0.072 | N10: 0.072 | O10: 0 | P10: 0 | Q10: 100 | R10: 100 | S10: 100 | T10: 100 | U10: 1.1907276 | V10: 1.1631508 | W10: 0.07364654 | X10: 0.068278841 | Y10: 0.074723546 | Z10: 0.074723546
A11: 605 | B11: 35 | C11: 0 | D11: 0 | E11: =_xlfn.CONCAT(C11,D11) -> 00 | F11: 0.18057448 | G11: 35.308815 | H11: =F11/G11 -> 0.0051141471 | I11: 0.606 | J11: 0.38888889 | K11: 0.024 | L11: 0.189 | M11: 0.013 | N11: 0.045 | O11: 0 | P11: 100 | Q11: 100 | R11: 100 | S11: 100 | T11: 100 | U11: 0.93140437 | V11: 0.49247649 | W11: 0.024292693 | X11: 0.20948722 | Y11: 0.01308524 | Z11: 0.046043939
A12: 299 | B12: 30 | C12: 0 | D12: 0 | E12: =_xlfn.CONCAT(C12,D12) -> 00 | F12: 0.18639675 | G12: 28.16863 | H12: =F12/G12 -> 0.0066171749 | I12: 0.691 | J12: 0.8 | K12: 0.011 | L12: 0.013 | M12: 0.014 | N12: 0.001 | O12: 0 | P12: 0 | Q12: 100 | R12: 100 | S12: 100 | T12: 100 | U12: 1.174414 | V12: 1.6094379 | W12: 0.011060947 | X12: 0.01308524 | Y12: 0.014098924 | Z12: 0.0010005003
A13: 331 | B13: 90 | C13: 0 | D13: 0 | E13: =_xlfn.CONCAT(C13,D13) -> 00 | F13: 0.23666473 | G13: 34.338533 | H13: =F13/G13 -> 0.0068921037 | I13: 0.547 | J13: 0.62857143 | K13: 0.011 | L13: 0.07 | M13: 0.01 | N13: 0.012 | O13: 0 | P13: 0 | Q13: 100 | R13: 100 | S13: 100 | T13: 100 | U13: 0.79186315 | V13: 0.9903987 | W13: 0.011060947 | X13: 0.072570693 | Y13: 0.010050336 | Z13: 0.012072581
... A1001: 58 | B1001: 95 | C1001: 1 | D1001: 1 | E1001: =_xlfn.CONCAT(C1001,D1001) -> 11 | F1001: 11.610211 | G1001: 20.333781 | H1001: =F1001/G1001 -> 0.57098139 | I1001: 0.606 | J1001: 0.60240964 | K1001: 0.686 | L1001: 0.633 | M1001: 0.708 | N1001: 0.641 | O1001: 100 | P1001: 100 | Q1001: 100 | R1001: 100 | S1001: 100 | T1001: 100 | U1001: 0.50087529 | V1001: 0.5068176 | W1001: 0.37687765 | X1001: 0.45728486 | Y1001: 0.34531119 | Z1001: 0.44472582

Sheet DR.LH
A1: trial | B1: taxon | C1: x | D1: y | E1: xy | F1: terminal | G1: height | H1: terminal.std | I1: p.bb | J1: p.nb | K1: p.ind.b | L1: p.dep.b | M1: p.ind.rj | N1: p.dep.rj | O1: c.bb | P1: c.nb | Q1: c.ind.b | R1: c.dep.b | S1: c.ind.rj | T1: c.dep.rj | U1: ll.bb | V1: ll.nb | W1: ll.ind.b | X1: ll.dep.b | Y1: ll.ind.rj | Z1: ll.dep.rj
A2: 133 | B2: 14 | C2: 0 | D2: 0 | E2: =_xlfn.CONCAT(C2,D2) -> 00 | F2: 0.012332297 | G2: 25.740445 | H2: =F2/G2 -> 0.00047910191 | I2: 0.768 | J2: 0.70588235 | K2: 0.004 | L2: 0.028 | M2: 0.001 | N2: 0.006 | O2: 0 | P2: 0 | Q2: 100 | R2: 100 | S2: 100 | T2: 100 | U2: 1.4610179 | V2: 1.2237754 | W2: 0.0040080214 | X2: 0.028399475 | Y2: 0.0010005003 | Z2: 0.0060180723
