Workbook

Sheet metadata
A1: summary
A2: scenario | B2: Evolutionary scenario (Q matrix) we used to simulate traits X and Y
B3: DEP3.L: Very high dependency, low rates
B4: DEP3.M: Very high dependency, medium rates
B5: DEP3.H: Very high dependency, high rates
A6: test.00 | B6: Count of the test taxon with X = 0 and Y = 0 across the 1,000 trials
A7: test.01 | B7: Count of the test taxon with X = 0 and Y = 1 across the 1,000 trials
A8: test.10 | B8: Count of the test taxon with X = 1 and Y = 0 across the 1,000 trials
A9: test.11 | B9: Count of the test taxon with X = 1 and Y = 1 across the 1,000 trials
A10: acc.bb | B10: Accuracy of the Bayesian Beta-Binomial prediction method
A11: acc.nb | B11: Accuracy of the Naive Bayes prediction method
A12: acc.ind.rj | B12: Accuracy of the RJMCMC-Discrete-Independent (BayesTraits) prediction method
A13: acc.dep.rj | B13: Accuracy of the RJMCMC-Discrete-Dependent (BayesTraits) prediction method
B14: Color: 0
B15: Color: 0.5
B16: Color: 1
A17: mll.bb | B17: Median log loss of the Bayesian Beta-Binomial prediction method
A18: mll.nb | B18: Median log loss of the Naive Bayes prediction method
A19: mll.ind.rj | B19: Median log loss of the RJMCMC-Discrete-Independent (BayesTraits) prediction method
A20: mll.dep.rj | B20: Median log loss of the RJMCMC-Discrete-Dependent (BayesTraits) prediction method
B21: Color: Log-loss = 2.302585 [equivalent to predicted P(Y=1) = 0.1, when the true state of trait Y of the test taxon is 1, or vice versa]
B22: Color: Log-loss = 0.6931472 [equivalent to predicted P(Y=1) = 0.5]
B23: Color: Log-loss = 0.1053605 [equivalent to predicted P(Y=1) = 0.1, when the true state of trait Y of the test taxon is 0, or vice versa]
A25: DEP3.L-DEP3.H
A26: trial | B26: Trial number
A27: taxon | B27: Test taxon (the target taxon or the taxon that was being predicted)
A28: x | B28: True state of trait X of the test taxon
A29: y | B29: True state of trait Y of the test taxon
A30: xy | B30: Concatenated states of trait X and trait Y of the test taxon
B31: Color: 00
B32: Color: 01
B33: Color: 10
B34: Color: 11
A35: terminal | B35: Terminal branch length of the test taxon
B36: Color: Maximum terminal branch length
B37: Color: Median terminal branch length
B38: Color: Minimum terminal branch length
A39: p.bb | B39: Predicted probability of Y = 1 in the test taxon, coming from the Bayesian Beta-Binomial model
A40: p.nb | B40: Predicted probability of Y = 1 in the test taxon, coming from the Naive Bayes method
A41: p.ind.rj | B41: Predicted probability of Y = 1 in the test taxon, coming from the RJMCMC-Discrete-Independent method (BayesTraits)
...

Sheet summary
A1: ALL
A2: scenario | B2: test.00 | C2: test.01 | D2: test.10 | E2: test.11 | G2: acc.bb | H2: acc.nb | I2: acc.ind.rj | J2: acc.dep.rj | L2: mll.bb | M2: mll.nb | N2: mll.ind.rj | O2: mll.dep.rj
A3: DEP3.L | B3: =COUNTIF('DEP3.L'!E2:E1001,"00") -> 777 | C3: =COUNTIF('DEP3.L'!E2:E1001,"01") -> 188 | D3: =COUNTIF('DEP3.L'!E2:E1001,"10") -> 0 | E3: =COUNTIF('DEP3.L'!E2:E1001,"11") -> 35 | G3: =COUNTIF('DEP3.L'!K2:K1001,100)/1000 -> 0.783 | H3: =COUNTIF('DEP3.L'!L2:L1001,100)/1000 -> 0.815 | I3: =COUNTIF('DEP3.L'!M2:M1001,100)/1000 -> 0.969 | J3: =COUNTIF('DEP3.L'!N2:N1001,100)/1000 -> 0.971 | L3: =MEDIAN('DEP3.L'!O2:O1001) -> 0.23635565 | M3: =MEDIAN('DEP3.L'!P2:P1001) -> 0.19977684 | N3: =MEDIAN('DEP3.L'!Q2:Q1001) -> 0.01308524 | O3: =MEDIAN('DEP3.L'!R2:R1001) -> 0.014098924
A4: DEP3.M | B4: =COUNTIF('DEP3.M'!E2:E1001,"00") -> 559 | C4: =COUNTIF('DEP3.M'!E2:E1001,"01") -> 323 | D4: =COUNTIF('DEP3.M'!E2:E1001,"10") -> 0 | E4: =COUNTIF('DEP3.M'!E2:E1001,"11") -> 118 | G4: =COUNTIF('DEP3.M'!K2:K1001,100)/1000 -> 0.635 | H4: =COUNTIF('DEP3.M'!L2:L1001,100)/1000 -> 0.702 | I4: =COUNTIF('DEP3.M'!M2:M1001,100)/1000 -> 0.931 | J4: =COUNTIF('DEP3.M'!N2:N1001,100)/1000 -> 0.933 | L4: =MEDIAN('DEP3.M'!O2:O1001) -> 0.55599772 | M4: =MEDIAN('DEP3.M'!P2:P1001) -> 0.41765578 | N4: =MEDIAN('DEP3.M'!Q2:Q1001) -> 0.035627178 | O4: =MEDIAN('DEP3.M'!R2:R1001) -> 0.034591445
A5: DEP3.H | B5: =COUNTIF('DEP3.H'!E2:E1001,"00") -> 447 | C5: =COUNTIF('DEP3.H'!E2:E1001,"01") -> 340 | D5: =COUNTIF('DEP3.H'!E2:E1001,"10") -> 3 | E5: =COUNTIF('DEP3.H'!E2:E1001,"11") -> 210 | G5: =COUNTIF('DEP3.H'!K2:K1001,100)/1000 -> 0.58 | H5: =COUNTIF('DEP3.H'!L2:L1001,100)/1000 -> 0.672 | I5: =COUNTIF('DEP3.H'!M2:M1001,100)/1000 -> 0.894 | J5: =COUNTIF('DEP3.H'!N2:N1001,100)/1000 -> 0.904 | L5: =MEDIAN('DEP3.H'!O2:O1001) -> 0.6558514 | M5: =MEDIAN('DEP3.H'!P2:P1001) -> 0.55180121 | N5: =MEDIAN('DEP3.H'!Q2:Q1001) -> 0.065071997 | O5: =MEDIAN('DEP3.H'!R2:R1001) -> 0.058688996
A7: TRUE STATE OF TEST TAXON: 00
A8: scenario | B8: test.00 | C8: test.01 | D8: test.10 | E8: test.11 | G8: acc.bb | H8: acc.nb | I8: acc.ind.rj | J8: acc.dep.rj | L8: mll.bb | M8: mll.nb | N8: mll.ind.rj | O8: mll.dep.rj
A9: DEP3.L | B9: =B3 -> 777 | C9: 0 | D9: 0 | E9: 0 | G9: =COUNTIFS('DEP3.L'!K2:K1001,100,'DEP3.L'!$E$2:$E$1001,"00")/$B$9 -> 0.97168597 | H9: =COUNTIFS('DEP3.L'!L2:L1001,100,'DEP3.L'!$E$2:$E$1001,"00")/$B$9 -> 0.98584299 | I9: =COUNTIFS('DEP3.L'!M2:M1001,100,'DEP3.L'!$E$2:$E$1001,"00")/$B$9 -> 0.98712999 | J9: =COUNTIFS('DEP3.L'!N2:N1001,100,'DEP3.L'!$E$2:$E$1001,"00")/$B$9 -> 0.98841699 | L9: {=MEDIAN(IF('DEP3.L'!$E$2:$E$1001="00",'DEP3.L'!O2:O1001))} -> 0.18995058 | M9: {=MEDIAN(IF('DEP3.L'!$E$2:$E$1001="00",'DEP3.L'!P2:P1001))} -> 0.17185026 | N9: {=MEDIAN(IF('DEP3.L'!$E$2:$E$1001="00",'DEP3.L'!Q2:Q1001))} -> 0.014098924 | O9: {=MEDIAN(IF('DEP3.L'!$E$2:$E$1001="00",'DEP3.L'!R2:R1001))} -> 0.014098924
A10: DEP3.M | B10: =B4 -> 559 | C10: 0 | D10: 0 | E10: 0 | G10: =COUNTIFS('DEP3.M'!K2:K1001,100,'DEP3.M'!$E$2:$E$1001,"00")/$B$10 -> 0.86404293 | H10: =COUNTIFS('DEP3.M'!L2:L1001,100,'DEP3.M'!$E$2:$E$1001,"00")/$B$10 -> 0.95169946 | I10: =COUNTIFS('DEP3.M'!M2:M1001,100,'DEP3.M'!$E$2:$E$1001,"00")/$B$10 -> 0.94633274 | J10: =COUNTIFS('DEP3.M'!N2:N1001,100,'DEP3.M'!$E$2:$E$1001,"00")/$B$10 -> 0.94812165 | L10: {=MEDIAN(IF('DEP3.M'!$E$2:$E$1001="00",'DEP3.M'!O2:O1001))} -> 0.449417 | M10: {=MEDIAN(IF('DEP3.M'!$E$2:$E$1001="00",'DEP3.M'!P2:P1001))} -> 0.3624345 | N10: {=MEDIAN(IF('DEP3.M'!$E$2:$E$1001="00",'DEP3.M'!Q2:Q1001))} -> 0.036663984 | O10: {=MEDIAN(IF('DEP3.M'!$E$2:$E$1001="00",'DEP3.M'!R2:R1001))} -> 0.03978087
A11: DEP3.H | B11: =B5 -> 447 | C11: 0 | D11: 0 | E11: 0 | G11: =COUNTIFS('DEP3.H'!K2:K1001,100,'DEP3.H'!$E$2:$E$1001,"00")/$B$11 -> 0.40044743 | H11: =COUNTIFS('DEP3.H'!L2:L1001,100,'DEP3.H'!$E$2:$E$1001,"00")/$B$11 -> 0.86129754 | I11: =COUNTIFS('DEP3.H'!M2:M1001,100,'DEP3.H'!$E$2:$E$1001,"00")/$B$11 -> 0.87919463 | J11: =COUNTIFS('DEP3.H'!N2:N1001,100,'DEP3.H'!$E$2:$E$1001,"00")/$B$11 -> 0.89932886 | L11: {=MEDIAN(IF('DEP3.H'!$E$2:$E$1001="00",'DEP3.H'!O2:O1001))} -> 0.74865989 | M11: {=MEDIAN(IF('DEP3.H'!$E$2:$E$1001="00",'DEP3.H'!P2:P1001))} -> 0.51794309 | N11: {=MEDIAN(IF('DEP3.H'!$E$2:$E$1001="00",'DEP3.H'!Q2:Q1001))} -> 0.085557888 | O11: {=MEDIAN(IF('DEP3.H'!$E$2:$E$1001="00",'DEP3.H'!R2:R1001))} -> 0.089924708
A13: TRUE STATE OF TEST TAXON: 01
A14: scenario | B14: test.00 | C14: test.01 | D14: test.10 | E14: test.11 | G14: acc.bb | H14: acc.nb | I14: acc.ind.rj | J14: acc.dep.rj | L14: mll.bb | M14: mll.nb | N14: mll.ind.rj | O14: mll.dep.rj
A15: DEP3.L | B15: 0 | C15: =C3 -> 188 | D15: 0 | E15: 0 | G15: =COUNTIFS('DEP3.L'!K2:K1001,100,'DEP3.L'!$E$2:$E$1001,"01")/$C$15 -> 0.095744681 | H15: =COUNTIFS('DEP3.L'!L2:L1001,100,'DEP3.L'!$E$2:$E$1001,"01")/$C$15 -> 0.079787234 | I15: =COUNTIFS('DEP3.L'!M2:M1001,100,'DEP3.L'!$E$2:$E$1001,"01")/$C$15 -> 0.89893617 | J15: =COUNTIFS('DEP3.L'!N2:N1001,100,'DEP3.L'!$E$2:$E$1001,"01")/$C$15 -> 0.89893617 | L15: {=MEDIAN(IF('DEP3.L'!$E$2:$E$1001="01",'DEP3.L'!O2:O1001))} -> 1.3001183 | M15: {=MEDIAN(IF('DEP3.L'!$E$2:$E$1001="01",'DEP3.L'!P2:P1001))} -> 1.4209147 | N15: {=MEDIAN(IF('DEP3.L'!$E$2:$E$1001="01",'DEP3.L'!Q2:Q1001))} -> 0.013592082 | O15: {=MEDIAN(IF('DEP3.L'!$E$2:$E$1001="01",'DEP3.L'!R2:R1001))} -> 0.018163971
A16: DEP3.M | B16: 0 | C16: =C4 -> 323 | D16: 0 | E16: 0 | G16: =COUNTIFS('DEP3.M'!K2:K1001,100,'DEP3.M'!$E$2:$E$1001,"01")/$C$16 -> 0.29411765 | H16: =COUNTIFS('DEP3.M'!L2:L1001,100,'DEP3.M'!$E$2:$E$1001,"01")/$C$16 -> 0.16099071 | I16: =COUNTIFS('DEP3.M'!M2:M1001,100,'DEP3.M'!$E$2:$E$1001,"01")/$C$16 -> 0.88854489 | J16: =COUNTIFS('DEP3.M'!N2:N1001,100,'DEP3.M'!$E$2:$E$1001,"01")/$C$16 -> 0.88235294 | L16: {=MEDIAN(IF('DEP3.M'!$E$2:$E$1001="01",'DEP3.M'!O2:O1001))} -> 0.87227385 | M16: {=MEDIAN(IF('DEP3.M'!$E$2:$E$1001="01",'DEP3.M'!P2:P1001))} -> 1.0399636 | N16: {=MEDIAN(IF('DEP3.M'!$E$2:$E$1001="01",'DEP3.M'!Q2:Q1001))} -> 0.040821995 | O16: {=MEDIAN(IF('DEP3.M'!$E$2:$E$1001="01",'DEP3.M'!R2:R1001))} -> 0.050241216
A17: DEP3.H | B17: 0 | C17: =C5 -> 340 | D17: 0 | E17: 0 | G17: =COUNTIFS('DEP3.H'!K2:K1001,100,'DEP3.H'!$E$2:$E$1001,"01")/$C$17 -> 0.71764706 | H17: =COUNTIFS('DEP3.H'!L2:L1001,100,'DEP3.H'!$E$2:$E$1001,"01")/$C$17 -> 0.22647059 | I17: =COUNTIFS('DEP3.H'!M2:M1001,100,'DEP3.H'!$E$2:$E$1001,"01")/$C$17 -> 0.87058824 | J17: =COUNTIFS('DEP3.H'!N2:N1001,100,'DEP3.H'!$E$2:$E$1001,"01")/$C$17 -> 0.85882353 | L17: {=MEDIAN(IF('DEP3.H'!$E$2:$E$1001="01",'DEP3.H'!O2:O1001))} -> 0.58698698 | M17: {=MEDIAN(IF('DEP3.H'!$E$2:$E$1001="01",'DEP3.H'!P2:P1001))} -> 0.85208259 | N17: {=MEDIAN(IF('DEP3.H'!$E$2:$E$1001="01",'DEP3.H'!Q2:Q1001))} -> 0.058688996 | O17: {=MEDIAN(IF('DEP3.H'!$E$2:$E$1001="01",'DEP3.H'!R2:R1001))} -> 0.10147932
A19: TRUE STATE OF TEST TAXON: 10
A20: scenario | B20: test.00 | C20: test.01 | D20: test.10 | E20: test.11 | G20: acc.bb | H20: acc.nb | I20: acc.ind.rj | J20: acc.dep.rj | L20: mll.bb | M20: mll.nb | N20: mll.ind.rj | O20: mll.dep.rj
A21: DEP3.L | B21: 0 | C21: 0 | D21: =D3 -> 0 | E21: 0 | G21: =COUNTIFS('DEP3.L'!K2:K1001,100,'DEP3.L'!$E$2:$E$1001,"10")/$D$21 -> #DIV/0! | H21: =COUNTIFS('DEP3.L'!L2:L1001,100,'DEP3.L'!$E$2:$E$1001,"10")/$D$21 -> #DIV/0! | I21: =COUNTIFS('DEP3.L'!M2:M1001,100,'DEP3.L'!$E$2:$E$1001,"10")/$D$21 -> #DIV/0! | J21: =COUNTIFS('DEP3.L'!N2:N1001,100,'DEP3.L'!$E$2:$E$1001,"10")/$D$21 -> #DIV/0! | L21: {=MEDIAN(IF('DEP3.L'!$E$2:$E$1001="10",'DEP3.L'!O2:O1001))} -> #NUM! | M21: {=MEDIAN(IF('DEP3.L'!$E$2:$E$1001="10",'DEP3.L'!P2:P1001))} -> #NUM! | N21: {=MEDIAN(IF('DEP3.L'!$E$2:$E$1001="10",'DEP3.L'!Q2:Q1001))} -> #NUM! | O21: {=MEDIAN(IF('DEP3.L'!$E$2:$E$1001="10",'DEP3.L'!R2:R1001))} -> #NUM!
A22: DEP3.M | B22: 0 | C22: 0 | D22: =D4 -> 0 | E22: 0 | G22: =COUNTIFS('DEP3.M'!K2:K1001,100,'DEP3.M'!$E$2:$E$1001,"10")/$D$22 -> #DIV/0! | H22: =COUNTIFS('DEP3.M'!L2:L1001,100,'DEP3.M'!$E$2:$E$1001,"10")/$D$22 -> #DIV/0! | I22: =COUNTIFS('DEP3.M'!M2:M1001,100,'DEP3.M'!$E$2:$E$1001,"10")/$D$22 -> #DIV/0! | J22: =COUNTIFS('DEP3.M'!N2:N1001,100,'DEP3.M'!$E$2:$E$1001,"10")/$D$22 -> #DIV/0! | L22: {=MEDIAN(IF('DEP3.M'!$E$2:$E$1001="10",'DEP3.M'!O2:O1001))} -> #NUM! | M22: {=MEDIAN(IF('DEP3.M'!$E$2:$E$1001="10",'DEP3.M'!P2:P1001))} -> #NUM! | N22: {=MEDIAN(IF('DEP3.M'!$E$2:$E$1001="10",'DEP3.M'!Q2:Q1001))} -> #NUM! | O22: {=MEDIAN(IF('DEP3.M'!$E$2:$E$1001="10",'DEP3.M'!R2:R1001))} -> #NUM!
A23: DEP3.H | B23: 0 | C23: 0 | D23: =D5 -> 3 | E23: 0 | G23: =COUNTIFS('DEP3.H'!K2:K1001,100,'DEP3.H'!$E$2:$E$1001,"10")/$D$23 -> 0 | H23: =COUNTIFS('DEP3.H'!L2:L1001,100,'DEP3.H'!$E$2:$E$1001,"10")/$D$23 -> 0 | I23: =COUNTIFS('DEP3.H'!M2:M1001,100,'DEP3.H'!$E$2:$E$1001,"10")/$D$23 -> 0.66666667 | J23: =COUNTIFS('DEP3.H'!N2:N1001,100,'DEP3.H'!$E$2:$E$1001,"10")/$D$23 -> 0.66666667 | L23: {=MEDIAN(IF('DEP3.H'!$E$2:$E$1001="10",'DEP3.H'!O2:O1001))} -> 0.80073239 | M23: {=MEDIAN(IF('DEP3.H'!$E$2:$E$1001="10",'DEP3.H'!P2:P1001))} -> 2.3895965 | N23: {=MEDIAN(IF('DEP3.H'!$E$2:$E$1001="10",'DEP3.H'!Q2:Q1001))} -> 0.03978087 | O23: {=MEDIAN(IF('DEP3.H'!$E$2:$E$1001="10",'DEP3.H'!R2:R1001))} -> 0.040821995
A25: TRUE STATE OF TEST TAXON: 11
A26: scenario | B26: test.00 | C26: test.01 | D26: test.10 | E26: test.11 | G26: acc.bb | H26: acc.nb | I26: acc.ind.rj | J26: acc.dep.rj | L26: mll.bb | M26: mll.nb | N26: mll.ind.rj | O26: mll.dep.rj
A27: DEP3.L | B27: 0 | C27: 0 | D27: 0 | E27: =E3 -> 35 | G27: =COUNTIFS('DEP3.L'!K2:K1001,100,'DEP3.L'!$E$2:$E$1001,"11")/$E$27 -> 0.28571429 | H27: =COUNTIFS('DEP3.L'!L2:L1001,100,'DEP3.L'!$E$2:$E$1001,"11")/$E$27 -> 0.97142857 | I27: =COUNTIFS('DEP3.L'!M2:M1001,100,'DEP3.L'!$E$2:$E$1001,"11")/$E$27 -> 0.94285714 | J27: =COUNTIFS('DEP3.L'!N2:N1001,100,'DEP3.L'!$E$2:$E$1001,"11")/$E$27 -> 0.97142857 | L27: {=MEDIAN(IF('DEP3.L'!$E$2:$E$1001="11",'DEP3.L'!O2:O1001))} -> 1.0272223 | M27: {=MEDIAN(IF('DEP3.L'!$E$2:$E$1001="11",'DEP3.L'!P2:P1001))} -> 1.000005e-05 | N27: {=MEDIAN(IF('DEP3.L'!$E$2:$E$1001="11",'DEP3.L'!Q2:Q1001))} -> 0.0070246149 | O27: {=MEDIAN(IF('DEP3.L'!$E$2:$E$1001="11",'DEP3.L'!R2:R1001))} -> 1.000005e-05
A28: DEP3.M | B28: 0 | C28: 0 | D28: 0 | E28: =E4 -> 118 | G28: =COUNTIFS('DEP3.M'!K2:K1001,100,'DEP3.M'!$E$2:$E$1001,"11")/$E$28 -> 0.48305085 | H28: =COUNTIFS('DEP3.M'!L2:L1001,100,'DEP3.M'!$E$2:$E$1001,"11")/$E$28 -> 1 | I28: =COUNTIFS('DEP3.M'!M2:M1001,100,'DEP3.M'!$E$2:$E$1001,"11")/$E$28 -> 0.97457627 | J28: =COUNTIFS('DEP3.M'!N2:N1001,100,'DEP3.M'!$E$2:$E$1001,"11")/$E$28 -> 1 | L28: {=MEDIAN(IF('DEP3.M'!$E$2:$E$1001="11",'DEP3.M'!O2:O1001))} -> 0.69916525 | M28: {=MEDIAN(IF('DEP3.M'!$E$2:$E$1001="11",'DEP3.M'!P2:P1001))} -> 1.000005e-05 | N28: {=MEDIAN(IF('DEP3.M'!$E$2:$E$1001="11",'DEP3.M'!Q2:Q1001))} -> 0.018673395 | O28: {=MEDIAN(IF('DEP3.M'!$E$2:$E$1001="11",'DEP3.M'!R2:R1001))} -> 1.000005e-05
A29: DEP3.H | B29: 0 | C29: 0 | D29: 0 | E29: =E5 -> 210 | G29: =COUNTIFS('DEP3.H'!K2:K1001,100,'DEP3.H'!$E$2:$E$1001,"11")/$E$29 -> 0.74761905 | H29: =COUNTIFS('DEP3.H'!L2:L1001,100,'DEP3.H'!$E$2:$E$1001,"11")/$E$29 -> 1 | I29: =COUNTIFS('DEP3.H'!M2:M1001,100,'DEP3.H'!$E$2:$E$1001,"11")/$E$29 -> 0.96666667 | J29: =COUNTIFS('DEP3.H'!N2:N1001,100,'DEP3.H'!$E$2:$E$1001,"11")/$E$29 -> 0.99047619 | L29: {=MEDIAN(IF('DEP3.H'!$E$2:$E$1001="11",'DEP3.H'!O2:O1001))} -> 0.56125171 | M29: {=MEDIAN(IF('DEP3.H'!$E$2:$E$1001="11",'DEP3.H'!P2:P1001))} -> 1.000005e-05 | N29: {=MEDIAN(IF('DEP3.H'!$E$2:$E$1001="11",'DEP3.H'!Q2:Q1001))} -> 0.047091608 | O29: {=MEDIAN(IF('DEP3.H'!$E$2:$E$1001="11",'DEP3.H'!R2:R1001))} -> 1.000005e-05

Sheet DEP3.L
A1: trial | B1: taxon | C1: x | D1: y | E1: xy | F1: terminal | G1: p.bb | H1: p.nb | I1: p.ind.rj | J1: p.dep.rj | K1: c.bb | L1: c.nb | M1: c.ind.rj | N1: c.dep.rj | O1: ll.bb | P1: ll.nb | Q1: ll.ind.rj | R1: ll.dep.rj
A2: 26 | B2: 500 | C2: 0 | D2: 0 | E2: =_xlfn.CONCAT(C2,D2) -> 00 | F2: 4.5959497e-05 | G2: 0.173 | H2: 0.17373737 | I2: 0 | J2: 0 | K2: 100 | L2: 100 | M2: 100 | N2: 100 | O2: 0.18995058 | P2: 0.19084261 | Q2: 1.000005e-05 | R2: 1.000005e-05
A3: 707 | B3: 499 | C3: 0 | D3: 0 | E3: =_xlfn.CONCAT(C3,D3) -> 00 | F3: 0.00064157442 | G3: 0.121 | H3: 0.10441767 | I3: 0 | J3: 0 | K3: 100 | L3: 100 | M3: 100 | N3: 100 | O3: 0.12897038 | P3: 0.11028113 | Q3: 1.000005e-05 | R3: 1.000005e-05
A4: 688 | B4: 500 | C4: 0 | D4: 0 | E4: =_xlfn.CONCAT(C4,D4) -> 00 | F4: 0.00072115065 | G4: 0.156 | H4: 0.12704918 | I4: 0 | J4: 0 | K4: 100 | L4: 100 | M4: 100 | N4: 100 | O4: 0.16960278 | P4: 0.13587606 | Q4: 1.000005e-05 | R4: 1.000005e-05
A5: 430 | B5: 497 | C5: 0 | D5: 0 | E5: =_xlfn.CONCAT(C5,D5) -> 00 | F5: 0.00082767191 | G5: 0.142 | H5: 0.13426854 | I5: 0 | J5: 0 | K5: 100 | L5: 100 | M5: 100 | N5: 100 | O5: 0.15315118 | P5: 0.14418051 | Q5: 1.000005e-05 | R5: 1.000005e-05
A6: 476 | B6: 499 | C6: 0 | D6: 0 | E6: =_xlfn.CONCAT(C6,D6) -> 00 | F6: 0.0012716024 | G6: 0.132 | H6: 0.13480885 | I6: 0 | J6: 0 | K6: 100 | L6: 100 | M6: 100 | N6: 100 | O6: 0.14156356 | P6: 0.14480482 | Q6: 1.000005e-05 | R6: 1.000005e-05
A7: 679 | B7: 495 | C7: 0 | D7: 0 | E7: =_xlfn.CONCAT(C7,D7) -> 00 | F7: 0.0019390443 | G7: 0.296 | H7: 0.26709402 | I7: 0 | J7: 0 | K7: 100 | L7: 100 | M7: 100 | N7: 100 | O7: 0.35097692 | P7: 0.31073785 | Q7: 1.000005e-05 | R7: 1.000005e-05
A8: 540 | B8: 498 | C8: 0 | D8: 0 | E8: =_xlfn.CONCAT(C8,D8) -> 00 | F8: 0.0022162652 | G8: 0.503 | H8: 0.49068323 | I8: 0 | J8: 0 | K8: 0 | L8: 100 | M8: 100 | N8: 100 | O8: 0.69916525 | P8: 0.67468512 | Q8: 1.000005e-05 | R8: 1.000005e-05
A9: 94 | B9: 500 | C9: 0 | D9: 0 | E9: =_xlfn.CONCAT(C9,D9) -> 00 | F9: 0.0026502336 | G9: 0.076 | H9: 0.049180328 | I9: 0 | J9: 0 | K9: 100 | L9: 100 | M9: 100 | N9: 100 | O9: 0.079043207 | P9: 0.050430854 | Q9: 1.000005e-05 | R9: 1.000005e-05
A10: 16 | B10: 495 | C10: 0 | D10: 0 | E10: =_xlfn.CONCAT(C10,D10) -> 00 | F10: 0.0026937234 | G10: 0.22 | H10: 0.19341564 | I10: 0 | J10: 0 | K10: 100 | L10: 100 | M10: 100 | N10: 100 | O10: 0.24846136 | P10: 0.21494678 | Q10: 1.000005e-05 | R10: 1.000005e-05
A11: 812 | B11: 492 | C11: 0 | D11: 0 | E11: =_xlfn.CONCAT(C11,D11) -> 00 | F11: 0.003644141 | G11: 0.161 | H11: 0.16260163 | I11: 0.001 | J11: 0 | K11: 100 | L11: 100 | M11: 100 | N11: 100 | O11: 0.17554457 | P11: 0.17745537 | Q11: 0.0010005003 | R11: 1.000005e-05
A12: 429 | B12: 491 | C12: 0 | D12: 0 | E12: =_xlfn.CONCAT(C12,D12) -> 00 | F12: 0.0038076668 | G12: 0.21 | H12: 0.22177419 | I12: 0 | J12: 0.001 | K12: 100 | L12: 100 | M12: 100 | N12: 100 | O12: 0.23572233 | P12: 0.25073856 | Q12: 1.000005e-05 | R12: 0.0010005003
A13: 735 | B13: 495 | C13: 0 | D13: 0 | E13: =_xlfn.CONCAT(C13,D13) -> 00 | F13: 0.0039998654 | G13: 0.315 | H13: 0.30290456 | I13: 0 | J13: 0 | K13: 100 | L13: 100 | M13: 100 | N13: 100 | O13: 0.37833644 | P13: 0.36083295 | Q13: 1.000005e-05 | R13: 1.000005e-05
... A996: 723 | B996: 83 | C996: 1 | D996: 1 | E996: =_xlfn.CONCAT(C996,D996) -> 11 | F996: 0.97620099 | G996: 0.262 | H996: 1 | I996: 0.979 | J996: 0.99 | K996: 0 | L996: 100 | M996: 100 | N996: 100 | O996: 1.3394108 | P996: 1.000005e-05 | Q996: 0.021223636 | R996: 0.010050336
A997: 683 | B997: 184 | C997: 1 | D997: 1 | E997: =_xlfn.CONCAT(C997,D997) -> 11 | F997: 1.0406832 | G997: 0.173 | H997: NA | I997: 0.051 | J997: 0.441 | K997: 0 | L997: 100 | M997: 0 | N997: 0 | O997: 1.7544637 | Q997: 2.9759296 | R997: 0.8187104
A998: 355 | B998: 345 | C998: 1 | D998: 1 | E998: =_xlfn.CONCAT(C998,D998) -> 11 | F998: 1.6178554 | G998: 0.255 | H998: 1 | I998: 0.926 | J998: 0.995 | K998: 0 | L998: 100 | M998: 100 | N998: 100 | O998: 1.3664917 | P998: 1.000005e-05 | Q998: 0.076881044 | R998: 0.0050125418
A999: 367 | B999: 28 | C999: 1 | D999: 1 | E999: =_xlfn.CONCAT(C999,D999) -> 11 | F999: 1.8330974 | G999: 0.123 | H999: 1 | I999: 0.926 | J999: 0.986 | K999: 0 | L999: 100 | M999: 100 | N999: 100 | O999: 2.0955709 | P999: 1.000005e-05 | Q999: 0.076881044 | R999: 0.014098924
A1000: 464 | B1000: 26 | C1000: 1 | D1000: 1 | E1000: =_xlfn.CONCAT(C1000,D1000) -> 11 | F1000: 2.0110526 | G1000: 0.075 | H1000: 0 | I1000: 0.95 | J1000: 0.604 | K1000: 0 | L1000: 0 | M1000: 100 | N1000: 100 | O1000: 2.5902672 | P1000: 11.512925 | Q1000: 0.051293294 | R1000: 0.50418108
A1001: 720 | B1001: 13 | C1001: 1 | D1001: 1 | E1001: =_xlfn.CONCAT(C1001,D1001) -> 11 | F1001: 4.977212 | G1001: 0.129 | H1001: 1 | I1001: 0.143 | J1001: 0.981 | K1001: 0 | L1001: 100 | M1001: 0 | N1001: 100 | O1001: 2.0479429 | P1001: 1.000005e-05 | Q1001: 1.9449106 | R1001: 0.019182819

Sheet DEP3.M
A1: trial | B1: taxon | C1: x | D1: y | E1: xy | F1: terminal | G1: p.bb | H1: p.nb | I1: p.ind.rj | J1: p.dep.rj | K1: c.bb | L1: c.nb | M1: c.ind.rj | N1: c.dep.rj | O1: ll.bb | P1: ll.nb | Q1: ll.ind.rj | R1: ll.dep.rj
A2: 883 | B2: 497 | C2: 0 | D2: 0 | E2: =_xlfn.CONCAT(C2,D2) -> 00 | F2: 0.00034618232 | G2: 0.244 | H2: 0.21383648 | I2: 0 | J2: 0 | K2: 100 | L2: 100 | M2: 100 | N2: 100 | O2: 0.2797139 | P2: 0.24059046 | Q2: 1.000005e-05 | R2: 1.000005e-05
A3: 689 | B3: 499 | C3: 0 | D3: 0 | E3: =_xlfn.CONCAT(C3,D3) -> 00 | F3: 0.00096720469 | G3: 0.222 | H3: 0.20781893 | I3: 0 | J3: 0 | K3: 100 | L3: 100 | M3: 100 | N3: 100 | O3: 0.25102875 | P3: 0.23296529 | Q3: 1.000005e-05 | R3: 1.000005e-05
A4: 830 | B4: 500 | C4: 0 | D4: 0 | E4: =_xlfn.CONCAT(C4,D4) -> 00 | F4: 0.0015018165 | G4: 0.299 | H4: 0.27157895 | I4: 0 | J4: 0 | K4: 100 | L4: 100 | M4: 100 | N4: 100 | O4: 0.35524739 | P4: 0.31687603 | Q4: 1.000005e-05 | R4: 1.000005e-05
A5: 366 | B5: 495 | C5: 0 | D5: 0 | E5: =_xlfn.CONCAT(C5,D5) -> 00 | F5: 0.0033773484 | G5: 0.491 | H5: 0.41648107 | I5: 0 | J5: 0 | K5: 100 | L5: 100 | M5: 100 | N5: 100 | O5: 0.67530726 | P5: 0.53867838 | Q5: 1.000005e-05 | R5: 1.000005e-05
A6: 407 | B6: 498 | C6: 0 | D6: 0 | E6: =_xlfn.CONCAT(C6,D6) -> 00 | F6: 0.0041743743 | G6: 0.302 | H6: 0.19955157 | I6: 0.001 | J6: 0.001 | K6: 100 | L6: 100 | M6: 100 | N6: 100 | O6: 0.35953618 | P6: 0.22258317 | Q6: 0.0010005003 | R6: 0.0010005003
A7: 479 | B7: 494 | C7: 0 | D7: 0 | E7: =_xlfn.CONCAT(C7,D7) -> 00 | F7: 0.0042379052 | G7: 0.506 | H7: 0.44391408 | I7: 0 | J7: 0 | K7: 0 | L7: 100 | M7: 100 | N7: 100 | O7: 0.70521976 | P7: 0.58683247 | Q7: 1.000005e-05 | R7: 1.000005e-05
A8: 427 | B8: 492 | C8: 0 | D8: 0 | E8: =_xlfn.CONCAT(C8,D8) -> 00 | F8: 0.0091923062 | G8: 0.483 | H8: 0.28684211 | I8: 0.002 | J8: 0 | K8: 100 | L8: 100 | M8: 100 | N8: 100 | O8: 0.6597124 | P8: 0.33805243 | Q8: 0.0020020027 | R8: 1.000005e-05
A9: 288 | B9: 495 | C9: 0 | D9: 0 | E9: =_xlfn.CONCAT(C9,D9) -> 00 | F9: 0.010302079 | G9: 0.403 | H9: 0.35064935 | I9: 0.002 | J9: 0 | K9: 100 | L9: 100 | M9: 100 | N9: 100 | O9: 0.51583817 | P9: 0.43178242 | Q9: 0.0020020027 | R9: 1.000005e-05
A10: 846 | B10: 491 | C10: 0 | D10: 0 | E10: =_xlfn.CONCAT(C10,D10) -> 00 | F10: 0.010337214 | G10: 0.235 | H10: 0.21995927 | I10: 0.001 | J10: 0 | K10: 100 | L10: 100 | M10: 100 | N10: 100 | O10: 0.26787945 | P10: 0.24840914 | Q10: 0.0010005003 | R10: 1.000005e-05
A11: 811 | B11: 489 | C11: 0 | D11: 0 | E11: =_xlfn.CONCAT(C11,D11) -> 00 | F11: 0.013374269 | G11: 0.298 | H11: 0.24093817 | I11: 0 | J11: 0 | K11: 100 | L11: 100 | M11: 100 | N11: 100 | O11: 0.35382187 | P11: 0.27567204 | Q11: 1.000005e-05 | R11: 1.000005e-05
A12: 52 | B12: 492 | C12: 0 | D12: 0 | E12: =_xlfn.CONCAT(C12,D12) -> 00 | F12: 0.01663831 | G12: 0.444 | H12: 0.36504425 | I12: 0.003 | J12: 0.001 | K12: 100 | L12: 100 | M12: 100 | N12: 100 | O12: 0.58698698 | P12: 0.45419996 | Q12: 0.003004509 | R12: 0.0010005003
A13: 13 | B13: 485 | C13: 0 | D13: 0 | E13: =_xlfn.CONCAT(C13,D13) -> 00 | F13: 0.017157717 | G13: 0.468 | H13: 0.41666667 | I13: 0.001 | J13: 0.001 | K13: 100 | L13: 100 | M13: 100 | N13: 100 | O13: 0.63111179 | P13: 0.5389965 | Q13: 0.0010005003 | R13: 0.0010005003
... A1001: 819 | B1001: 94 | C1001: 1 | D1001: 1 | E1001: =_xlfn.CONCAT(C1001,D1001) -> 11 | F1001: 4.3603479 | G1001: 0.45 | H1001: 0.95348837 | I1001: 0.285 | J1001: 0.9 | K1001: 0 | L1001: 100 | M1001: 0 | N1001: 100 | O1001: 0.7985077 | P1001: 0.047628049 | Q1001: 1.2552661 | R1001: 0.10536052

Sheet DEP3.H
A1: trial | B1: taxon | C1: x | D1: y | E1: xy | F1: terminal | G1: p.bb | H1: p.nb | I1: p.ind.rj | J1: p.dep.rj | K1: c.bb | L1: c.nb | M1: c.ind.rj | N1: c.dep.rj | O1: ll.bb | P1: ll.nb | Q1: ll.ind.rj | R1: ll.dep.rj
A2: 677 | B2: 499 | C2: 0 | D2: 0 | E2: =_xlfn.CONCAT(C2,D2) -> 00 | F2: 0.00046427988 | G2: 0.662 | H2: 0.50439883 | I2: 0 | J2: 0 | K2: 0 | L2: 0 | M2: 100 | N2: 100 | O2: 1.0847094 | P2: 0.70198376 | Q2: 1.000005e-05 | R2: 1.000005e-05
A3: 454 | B3: 497 | C3: 0 | D3: 0 | E3: =_xlfn.CONCAT(C3,D3) -> 00 | F3: 0.0011801537 | G3: 0.453 | H3: 0.37647059 | I3: 0 | J3: 0 | K3: 100 | L3: 100 | M3: 100 | N3: 100 | O3: 0.60330648 | P3: 0.47235934 | Q3: 1.000005e-05 | R3: 1.000005e-05
A4: 45 | B4: 500 | C4: 0 | D4: 0 | E4: =_xlfn.CONCAT(C4,D4) -> 00 | F4: 0.0012311751 | G4: 0.498 | H4: 0.42401961 | I4: 0 | J4: 0 | K4: 100 | L4: 100 | M4: 100 | N4: 100 | O4: 0.68915516 | P4: 0.55168166 | Q4: 1.000005e-05 | R4: 1.000005e-05
A5: 662 | B5: 495 | C5: 0 | D5: 0 | E5: =_xlfn.CONCAT(C5,D5) -> 00 | F5: 0.0028917882 | G5: 0.558 | H5: 0.46462264 | I5: 0 | J5: 0.002 | K5: 0 | L5: 100 | M5: 100 | N5: 100 | O5: 0.8164454 | P5: 0.62478344 | Q5: 1.000005e-05 | R5: 0.0020020027
A6: 452 | B6: 493 | C6: 0 | D6: 0 | E6: =_xlfn.CONCAT(C6,D6) -> 00 | F6: 0.0039705953 | G6: 0.547 | H6: 0.4589372 | I6: 0.001 | J6: 0 | K6: 0 | L6: 100 | M6: 100 | N6: 100 | O6: 0.79186315 | P6: 0.61421992 | Q6: 0.0010005003 | R6: 1.000005e-05
A7: 293 | B7: 489 | C7: 0 | D7: 0 | E7: =_xlfn.CONCAT(C7,D7) -> 00 | F7: 0.0070426046 | G7: 0.437 | H7: 0.33333333 | I7: 0.002 | J7: 0.001 | K7: 100 | L7: 100 | M7: 100 | N7: 100 | O7: 0.57447565 | P7: 0.40546511 | Q7: 0.0020020027 | R7: 0.0010005003
A8: 349 | B8: 489 | C8: 0 | D8: 0 | E8: =_xlfn.CONCAT(C8,D8) -> 00 | F8: 0.0075954208 | G8: 0.528 | H8: 0.42298289 | I8: 0.001 | J8: 0.001 | K8: 0 | L8: 100 | M8: 100 | N8: 100 | O8: 0.75077629 | P8: 0.54988335 | Q8: 0.0010005003 | R8: 0.0010005003
A9: 469 | B9: 490 | C9: 0 | D9: 0 | E9: =_xlfn.CONCAT(C9,D9) -> 00 | F9: 0.0079049063 | G9: 0.531 | H9: 0.40547264 | I9: 0 | J9: 0.001 | K9: 0 | L9: 100 | M9: 100 | N9: 100 | O9: 0.75715251 | P9: 0.51998854 | Q9: 1.000005e-05 | R9: 0.0010005003
A10: 823 | B10: 486 | C10: 0 | D10: 0 | E10: =_xlfn.CONCAT(C10,D10) -> 00 | F10: 0.011871416 | G10: 0.565 | H10: 0.48129676 | I10: 0.002 | J10: 0.006 | K10: 0 | L10: 100 | M10: 100 | N10: 100 | O10: 0.83240925 | P10: 0.65642335 | Q10: 0.0020020027 | R10: 0.0060180723
A11: 776 | B11: 487 | C11: 0 | D11: 0 | E11: =_xlfn.CONCAT(C11,D11) -> 00 | F11: 0.012875139 | G11: 0.431 | H11: 0.375 | I11: 0 | J11: 0.003 | K11: 100 | L11: 100 | M11: 100 | N11: 100 | O11: 0.56387484 | P11: 0.47000363 | Q11: 1.000005e-05 | R11: 0.003004509
A12: 992 | B12: 478 | C12: 0 | D12: 0 | E12: =_xlfn.CONCAT(C12,D12) -> 00 | F12: 0.013990315 | G12: 0.616 | H12: 0.47337278 | I12: 0.004 | J12: 0.005 | K12: 0 | L12: 100 | M12: 100 | N12: 100 | O12: 0.95711273 | P12: 0.64126235 | Q12: 0.0040080214 | R12: 0.0050125418
A13: 353 | B13: 488 | C13: 0 | D13: 0 | E13: =_xlfn.CONCAT(C13,D13) -> 00 | F13: 0.016561981 | G13: 0.628 | H13: 0.45325779 | I13: 0.002 | J13: 0.006 | K13: 0 | L13: 100 | M13: 100 | N13: 100 | O13: 0.98886142 | P13: 0.60377787 | Q13: 0.0020020027 | R13: 0.0060180723
... A1001: 431 | B1001: 152 | C1001: 1 | D1001: 1 | E1001: =_xlfn.CONCAT(C1001,D1001) -> 11 | F1001: 3.7829053 | G1001: 0.632 | H1001: 0.97076023 | I1001: 0.665 | J1001: 0.986 | K1001: 100 | L1001: 100 | M1001: 100 | N1001: 100 | O1001: 0.45886588 | P1001: 0.029675768 | Q1001: 0.40796824 | R1001: 0.014098924
